Workbook
Name Budget_Revenue: #REF!
Name City: #REF!
Name Company_Name: #REF!
Name Contact_Address: #REF!
Name Contact_City: #REF!
Name Contact_ContactType: #REF!
Name Contact_Email: #REF!
Name Contact_First_Name: #REF!
Name Contact_Job_Title: #REF!
Name Contact_JobTitle: #REF!
Name Contact_Last_Name: #REF!
Name Contact_Phone: #REF!
Name Contact_Primary_Contact: #REF!
Name Contact_State: #REF!
Name Contact_Type: #REF!
Name Contact_Zip_Code: #REF!
Name Email: #REF!
Name Employees: #REF!
Name Env_Name: #REF!
Name Ex_Mod: #REF!
Name Exposure_Type_Cyber_Rating: #REF!
Name Final_Disposition: #REF!
Name Final_Disposition_Date: #REF!
Name Group: #REF!
Name Last_Contacted_BY: #REF!
Name Marketing_List_Create_Date: #REF!
Name Marketing_List_Name: #REF!
Name Marketing_Owner: #REF!
Name Next_Package_Expiration_Date: #REF!
Name Next_Workers_Compensation_Date: #REF!
Name Non_Profit: #REF!
Name Open_Recall_Flag: #REF!
Name Package_Carrier: #REF!
Name Package_Premium: #REF!
Name Phone: #REF!
Name Policy_Expiration_Date: #REF!
Name Primary_Lamb_Classification: #REF!
Name Prospect__Active_Status: #REF!
Name Prospect__Created_By: #REF!
Name Prospect_Budget_Revenue: #REF!
Name Prospect_City: #REF!
Name Prospect_Client_Status: #REF!
Name Prospect_Company_Name: #REF!
Name Prospect_Created_Date: #REF!
Name Prospect_Created_through: #REF!
Name Prospect_Employees: #REF!
Name Prospect_Ex_Mod: #REF!
Name Prospect_Final_Disposition: #REF!
Name Prospect_Final_Disposition_Date: #REF!
Name Prospect_Last_Contacted_By: #REF!
Name Prospect_Last_Contacted_Date: #REF!
Name Prospect_Last_Modified_By: #REF!
Name Prospect_Last_Modified_Date: #REF!
Name Prospect_NAICS: #REF!
Name Prospect_Next_Expiration_Date: #REF!
Name Prospect_Next_Package_Expiration_Date: #REF!
Name Prospect_Next_Workers_Compensation_Date: #REF!
Name Prospect_Non_Profit: #REF!
Name Prospect_NTEE: #REF!
Name Prospect_Package_Carrier: #REF!

Sheet Test User Level Data
A1: TestCase# | B1: User | C1: Type | D1: State | E1: Revenue Condition | F1: Revenue Limit | G1: Action | H1: Expected Output | I1: Actual Output | J1: Status
A2: TestCase#3 | B2: Bobby Sheppard | C2: Dynamic | D2: NJ | E2: Over | F2: 1000000 | G2: Publish | H2: Only Level1,Level2 Users are able to view the created list.
A3: TestCase#4 | B3: Tom | C3: Static | D3: NJ | E3: Over | F3: 4000000 | G3: Publish | H3: All User Levels are able to view the created list.
A4: TestCase#5 | B4: Conner Sweet | C4: Dynamic | D4: NJ | E4: Between | F4: 1000000,4000000 | G4: Publish | H4: All User Levels are able to view the created list.

Sheet Action Data
A1: TestCase# | B1: Name | C1: Type | D1: State | E1: Revenue Condition | F1: Revenue Limit | G1: Action | H1: Expected Output | I1: Actual Output | J1: Status
A2: TestCase#3 | B2: New Dynamic List-5 | C2: System-Default | D2: NJ | E2: Over | F2: 1000000 | G2: Save | H2: List Name is displayed in the list of Prospects and has Type as "System-Default" and Status as "System-Default"
A3: TestCase#5 | B3: New Dynamic List-6 | C3: Dynamic | D3: NJ | E3: Between | F3: 1000000,4000000 | G3: Save&Close | H3: List Name is displayed in the list of Prospects and has Type as "Dynamic" and Status as "Draft"
A4: TestCase#6 | B4: New Dynamic List-11 | C4: Dynamic | D4: NJ | E4: Upto | F4: 1000000 | G4: Published | H4: List Name is displayed in the list of Prospects and has Type as "Dynamic" and Status as "Published"

Sheet Group List Data- Contacts
A1: TestCase# | B1: Name | C1: Class | D1: Type | E1: Users | F1: Groups and Filters | G1: Condition | H1: Action | I1: Expected Output | J1: Actual Output | K1: Status
A2: TestCase#3 | B2: Static Test List for Contact #1 | C2: Whiteboard Activities | D2: Dynamic | E2: Kevin Corona,Manoj Peruri | F2: Group5,Filter3,Filter5 | G2: And | H2: Publish | I2: List is created with mentioned Name,Class,Type and Filters and then is assigned to mentioned Users

Sheet List Data
A1: TestCase# | B1: Name | C1: Type | D1: State | E1: Revenue Condition | F1: Revenue Limit | G1: Action | H1: Expected Output | I1: Actual Output | J1: Status
A2: TestCase#3 | B2: New Dynamic List-NJ-Over-1000000 | C2: Dynamic | D2: NJ | E2: Over | F2: 1000000 | G2: Publish | H2: All filtered prospect must have State as NJ and Revenue greater than 100000
A3: TestCase#5 | B3: New Dynamic List-NJ-Between-1000000 | C3: Dynamic | D3: NJ | E3: Between | F3: 1000000,4000000 | G3: Publish | H3: All filtered prospect must have State as NJ and Revenue Between 1000000 and 4000000
A4: TestCase#6 | B4: New Dynamic List-NJ-Between-1000000 | C4: Dynamic | D4: NJ | E4: Over | F4: 5000000 | G4: Publish | H4: All filtered prospect must have State as NJ and Revenue Over 5000000

Sheet Prospect Dial Disposition
A2: Did not Leave Voicemail | B2: Adoption & Foster Care
A3: Follow up to a Pitch | B3: Adult Day Care
A4: Left Voicemail | B4: Centers
A5: Non-Core/Remove from Database | B5: Charitable Food Organizations
A6: Pitched to Decision Maker | B6: Child Day Care and Special Learning
A7: Should not be on list | B7: Civil Rights & Advocacy Orgs
A8: No Pitch Made - Talk to Non Decision Maker | B8: Colleges & Universities
A9: No Pitch Made - Talked to Decision Maker | B9: Community Action Organizations
A10: Wrong Phone Number | B10: Crime & Legal Related
B11: Developmental Disability, Handicap Services & Disabilities
B12: Educational Service and Support, including Libraries
B13: Employment & Training Services
B14: Environment and Animal Related
B15: Foundations & Trusts
B16: Geriatric Services
B17: Health Care Services & Support
B18: Healthcare Advocacy
B19: Home Health
B20: Hospitals
B21: Housing & Shelter
B22: Human Service Orgs (Red Cross, Salvation Army, etc.)
... B40: Non-Core Other

Sheet Bind-Bound
A1: Reason
A2: 0-10%
A3: >10%
A4: Unknown
A5: Significantly lower deductibles offered by Lamb
A6: Better limits offered by Lamb
A7: Strong existing Lamb relationship or referral
A8: Lamb service value proposition

Sheet Coverage Checklist
A1: Property | B1: General Liability | C1: Professional Liability | D1: Auto | E1: Medical Malpractice | F1: Crime | G1: Umbrella | H1: Sexual Abuse & Molestation | I1: Educators Legal Liability | J1: Cyber | K1: Builders Risk | L1: Commercial Flood | M1: Earthquake | N1: Excess | O1: Fiduciary | P1: Owners Interest | Q1: Special Events | R1: Student Volunteer Accident | S1: Travel Accident | T1: Services Liability | U1: Workers Compensation | V1: Directors and Officers | W1: Employment Practices
A2: Improvements & Betterments Limit | B2: General Liability Deductible | C2: Deductible | D2: Personal Injury Protection (PIP) - Each Person | E2: Deductible | F2: Forgery or Alteration Deductible | G2: Retention (Umbrella Only) | H2: Deductible | I2: Educators Legal Liability Retention | J2: Breach Response Costs Retention | K2: Deductible | L2: Deductible | M2: Deductible | N2: Retention (Umbrella Only) | O2: Fiduciary Liability Retention | P2: General Liability Deductible | Q2: General Liability Deductible | R2: Deductible | S2: Deductible | T2: Easy & Comprehensive Claim & Incident Reporting | U2: State Safety Credit | V2: Directors & Officers Retention | W2: Employment Practices Liability Retention
A3: Flood Sublimit | B3: Employee Benefits Liability Deductible | C3: Designated Premises Limitation | D3: Optional Basic Economic Loss (OBEL) - Each Person | E3: Designated Premises Limitation | F3: Inside The Premises (Theft) Deductible | G3: General Liability | H3: Designated Premises Limitation | I3: Directors & Officers Retention | J3: Contingent/Dependent Business Interruption & Extra Expense Retention | K3: Flood Deductible | L3: Flood Limit | M3: Earthquake Limit | N3: General Liability | O3: Consolidated Omnibus Budget Reconciliation Act (COBRA) Violations Retention | P3: General Liability Deductible Trigger | Q3: Liquor Liability Deductible | R3: Policy Aggregate | S3: Accidental Death & Dismemberment - Principal Sum | T3: One-Stop Automated Access to All Available Claim Information | U3: Carrier Dividend Plan | V3: Anti-Trust Claims Retention | W3: Non-Monetary Suits Defense Retention
A4: Earthquake Sublimit | B4: Terrorism Risk Insurance Act of 2002 (TRIA) Coverage | C4: Specific Insureds Limitation | D4: Medical Payments - Each Person | E4: Specific Insureds Limitation | F4: Outside The Premises (Theft) Deductible | G4: Employee Benefits Liability | H4: Specific Insureds Limitation | I4: Employment Practices Liability Retention | J4: Reputational / Public Media Event Loss of Income Retention | K4: Earthquake Deductible | L4: Limit | M4: Limit - [User Entry - Allow User To Name] | N4: Professional Liability | O4: Excess Benefits Tax Retention | P4: Terrorism Risk Insurance Act of 2002 (TRIA) Coverage | Q4: Terrorism Risk Insurance Act of 2002 (TRIA) Coverage | R4: AD&D - Loss of Life | S4: AD&D - Loss of One Hand | T4: Claims Advocacy | U4: Do Multiple EINs Apply? | V4: Non-Monetary Suits Defense Retention | W4: Wage and Hour Claims Defense Retention
A5: Equipment Breakdown | B5: Designated Premises Limitation | C5: Defense Inside/Outside the Limit | D5: Statutory Uninsured Motorist | E5: Each Claim / Occurrence | F5: Computer Fraud Deductible | G5: Professional Liability | H5: Definition of "Insured" includes Volunteers | I5: Third Party Employment Practices Liability Retention | J5: Digital Asset Restoration Retention | K5: Policy Limit | L5: Coinsurance | M5: Coinsurance % | N5: Auto Liability | O5: Employee Retirement Income Security Act (ERISA) Violations Retention | P5: Bodily Injury - Mental Anguish & Emotional Distress Exclusion | Q5: Assault & Battery Exclusion | R5: AD&D - Loss of Both Hands | S5: AD&D - Loss of One Foot | T5: Claims-Reserve Reviews With Client’s Carriers | V5: Punitive Damages Exclusion | W5: Class-Action Suits Defense Retention
A6: Property In Transit | B6: Specific Insureds Limitation | C6: Limit | D6: Limit | E6: Aggregate | F6: Funds Transfer Fraud Deductible | G6: Sexual Abuse & Molestation | H6: Defense Inside/Outside the Limit | I6: Non-Monetary Suits Defense Retention | J6: Cyber Extortion / Ransomware Retention | K6: Soft Costs Limit | N6: Educators Legal Liability | O6: Health Insurance Portability and Accountability Act of 1996 (HIPAA) Violations Retention | P6: Specific Insureds Limitation | Q6: Liquor Liability Exclusion | R6: AD&D - Loss of Both Feet | S6: Loss of Sight in One Eye | T6: Claims Review Meetings | V6: Sexual Abuse & Molestation Exclusion | W6: Third Party Liability Retention
A7: Inland Marine Limit | B7: Lead Exclusion | C7: Claims Made | D7: Comprehensive | E7: Defense Inside/Outside the Limit | F7: Money Orders and Counterfeit Currency Deductible | G7: Auto Liability | H7: Limit | I7: Definition of "Insured" includes School Board / Board of Directors | J7: Invoice Manipulation Retention | K7: Earthquake Sublimit | N7: Employee Benefits Liability | O7: IRS Voluntary Settlement Program Violations Retention | P7: Punitive Damages Exclusion | Q7: Each Occurrence | R7: Loss of Sight in Both Eyes | S7: AD&D - Loss of Speech | T7: Experience Modification Review | V7: Each Claim / Occurrence | W7: Wage and Hour Claims Indemnity Retention
A8: Limit | B8: Corporal Punishment Exclusion | D8: Collision | E8: Claims Made | F8: Credit Card Fraud Deductible | G8: Employers Liability | I8: Definition of "Insured" includes Students | J8: Court Attendance Expense Retention | K8: Equipment Breakdown | N8: Sexual Abuse & Molestation | O8: Specific Plans/Insureds Limitation | P8: Each Occurrence | Q8: Products & Completed Operations Aggregate | R8: AD&D - Loss of Hearing | S8: AD&D - Loss of 2+: Hands & Feet | V8: Aggregate | W8: Class-Action Suits Indemnity Retention
A9: Coinsurance % | B9: Punitive Damages Exclusion | D9: Any Auto | F9: Theft of Client Property Deductible | G9: Educators Legal Liability | I9: Definition of "Insured" includes Parent Teacher Associations | J9: Security & Privacy Liability Retention | K9: Existing Structure - Business Personal Property Limit | N9: Employers Liability | O9: Each Claim / Occurrence | P9: Products & Completed Operations Aggregate | Q9: Damage To Rented Premises | R9: AD&D - Loss of 2+: Hands, Feet, Sight in One Eye | S9: AD&D - Loss of 2+: Hands, Feet, Sight in One Eye, Hearing, Speech | V9: Defense Inside/Outside the Limit | W9: Definition of "Third-Party Wrongful Act" includes Sexual Harrassment
A10: Valuation | B10: Bodily Injury - Mental Anguish & Emotional Distress Exclusion | D10: Owned Autos Only | F10: Theft of Client Property | G10: Medical Malpractice | I10: Punitive Damages Exclusion | J10: Bodily Injury - Mental Anguish & Emotional Distress Retention | K10: Hard Costs Limit | N10: Medical Malpractice | O10: Defense Inside/Outside the Limit | P10: Damage To Rented Premises | Q10: Liquor Liability - Each Occurrence | R10: AD&D - Quadriplegia | S10: AD&D - Paraplegia | V10: Defense Separate Limit | W10: Definition of "Third-Party Wrongful Act" includes Invasion of Privacy
A11: Agreed Value / Coinsurance | B11: General Aggregate Applies Per Location | D11: Owned Private Passenger Autos Only | F11: Credit Card Fraud | G11: Limit | I11: Sexual Abuse & Molestation Exclusion | J11: Property Damage Liability Retention | K11: Loss of Rents/Income Limit | N11: Employee Benefits Liability Sublimit | O11: Employee Retirement Income Security Act (ERISA) Violations Sublimit | P11: Limit - [User Entry - Allow User To Name] | Q11: Limit - [User Entry - Allow User To Name] | R11: AD&D - Hemiplegia | S11: AD&D - Uniplegia | V11: Side A (Individual Director) Separate Limit | W11: Punitive Damages Exclusion
A12: Wind/Hail | B12: Employee Benefits Liability Aggregate | D12: Owned Autos Other Than Private Passenger Autos Only | F12: Limit | G12: Policy Form | I12: Defense Inside/Outside the Limit | J12: Regulatory Fines & Penalties Retention | K12: Flood Sublimit | N12: Sexual Abuse & Molestation Sublimit | O12: Health Insurance Portability and Accountability Act of 1996 (HIPAA) Violations Sublimit | P12: General Aggregate | Q12: General Aggregate | R12: AD&D - Loss of Thumb and Index Finger on Same Hand | S12: AD&D - Loss of Life | V12: Non-Monetary Suits Defense Sublimit | W12: Each Claim / Occurrence
A13: Fungus, Wet Rot, Dry Rot | B13: Limit | D13: Owned Autos Subject To No-Fault | F13: Employee Theft / Dishonesty Deductible | G13: Claims Made | I13: Limit | J13: Payment Card Industry (PCI) Fines & Penalties Retention | K13: Existing Structure - Building Limit | N13: Educators Legal Liability Sublimit | O13: IRS Voluntary Settlement Program Violations Sublimit | P13: Personal & Advertising Injury | Q13: Personal & Advertising Injury | R13: Accidental Death & Dismemberment - Principal Sum | S13: AD&D - Loss of Both Hands | V13: Anti-Trust Sublimit | W13: Defense Inside/Outside the Limit
A14: Pollutant Clean-Up and Removal | B14: Claims Made | D14: Owned Autos Subject To A Compulsory Uninsured Motorist Law | I14: D&O Side A (Non-Indemnified Individuals Coverage) | J14: Business Interruption & Extra Expense Retention | K14: Existing Structure - Loss of Income | N14: Limit | O14: Aggregate | P14: Medical Expense | Q14: Medical Expense | R14: AD&D - Loss of One Hand | S14: AD&D - Loss of Both Feet | V14: Limit | W14: Third Party Liability Sublimit
A15: Accounts Receivable | D15: Specifically Described Autos | I15: D&O Side B (Indemnified Individuals Coverage) | J15: System Failure / Loss of Income Retention | K15: Coinsurance % | N15: General Liability Sublimit | O15: Defense Separate Limit | P15: Permission To Occupy | Q15: Liquor Liability Aggregate | R15: AD&D - Loss of One Foot | S15: Loss of Sight in Both Eyes | W15: Wage and Hour Claims (FLSA) Indemnity Sublimit
A16: Electronic Data Processing (EDP) | D16: Mobile Equipment Subject To Compulsory Or Financial Responsibility Or Other Motor Vehicle Insurance Law Only | I16: D&O Side C (Entity Coverage) | J16: Forensic Accounting Retention | K16: Valuation | N16: Professional Liability Sublimit | O16: Consolidated Omnibus Budget Reconciliation Act (COBRA) Violations Sublimit | P16: Address (Physical) | R16: Loss of Sight in One Eye | S16: AD&D - Loss of Hearing | W16: Class-Action Suits Indemnity Sublimit
A17: Mobile Equipment | D17: Claims Made | I17: Employment Practices Liability | J17: Bricking Retention | K17: Address (Physical) | N17: Auto Liability Sublimit | O17: Excess Benefits Tax Sublimit | P17: State (Physical) | R17: AD&D - Loss of Speech | S17: AD&D - Loss of 2+: Hands, Feet, Sight in One Eye | W17: Limit - [User Entry - Allow User To Name]
A18: Personal Property of Others | D18: Retro Date | I18: Third Party Employment Practices Liability | J18: Funds Transfer Fraud Retention | K18: State (Physical) | N18: Medical Malpractice Sublimit | O18: Limit | P18: Occupancy During Construction | R18: AD&D - Loss of 2+: Hands & Feet | S18: AD&D - Quadriplegia | W18: Aggregate
A19: Debris Removal | I19: Non-Monetary Suits Defense Sublimit | J19: Criminal Reward Expense Retention | K19: Square Footage Added | N19: Policy Form | P19: Construction Type | R19: AD&D - Loss of 2+: Hands, Feet, Sight in One Eye, Hearing, Speech | S19: AD&D - Hemiplegia | W19: Defense Separate Limit
A20: Business Income Waiting Period (Hours) | I20: Wage and Hour Claims (FLSA) Indemnity Sublimit | J20: Utility Fraud / Cryptojacking Retention | K20: Project Type | P20: City (Physical) | R20: AD&D - Paraplegia | S20: AD&D - Loss of Thumb and Index Finger on Same Hand | W20: Non-Monetary Suits Defense Sublimit
A21: Inland Marine Deductible | I21: Wage and Hour Claims (FLSA) Defense Sublimit | J21: Media Liability Retention | K21: Existing Structure - Square Footage | P21: Zip Code (Physical) | R21: AD&D - Uniplegia | W21: Wage and Hour Claims (FLSA) Defense Sublimit
A22: Flood Deductible | I22: Class-Action Suits Indemnity Sublimit | J22: Bodily Injury - Physical Injury, Disease, Death Retention | K22: Existing Structure - Year Built | P22: Project Type | W22: Class-Action Suits Defense Sublimit
A23: Earthquake Deductible | I23: Class-Action Suits Defense Sublimit | J23: Pollution Liability Retention | K23: City (Physical) | P23: Rate Per $1,000 Project Cost
A24: Named Storm Deductible | I24: Claims Made | J24: California Consumer Privacy Act (CCPA) Claims Retention | K24: Zip Code (Physical)
A25: Wind/Hail Deductible | J25: Sexual Abuse & Molestation Exclusion | K25: Occupancy During Construction
A26: Ordinance and Law A - Undamaged Portion | J26: Claims Originating from Employee Personal Devices ("BYOD") Exclusion | K26: Construction Type
A27: Ordinance and Law B - Demolition | J27: Management Liability (Directors & Officers) Exclusion | K27: Existing Structure - Construction Type
A28: Ordinance and Law C - Increased Cost of Construction | J28: Multi-Factor Authentication (MFA) Limitation/Warranty | K28: Existing Structure - Stories
J29: Policy Aggregate Limit
J30: Defense Separate Limit
J31: Breach Response Costs Separate Limit
J32: Contingent/Dependent Business Interruption & Extra Expense Sublimit
J33: Reputational / Public Media Event Loss of Income Sublimit
J34: Digital Asset Restoration Sublimit
J35: Cyber Extortion / Ransomware Sublimit
J36: Invoice Manipulation Sublimit
J37: Court Attendance Expense Sublimit
J38: Security & Privacy Liability Sublimit
J39: Bodily Injury - Mental Anguish & Emotional Distress Sublimit
J40: Property Damage Liability Sublimit
...

Sheet Policy-Term Values
A1: Policy Term | B1: Services | C1: Extra Exposures | D1: Coverages | E1: Special Circumstances | F1: Special Circumstances Workers Compensation | G1: Coverages for Management Package | H1: Services-Backup
A2: 2000-2001 | B2: Adoption & Foster Care | C2: Activities | D2: Property | E2: Owned Buildings | F2: Required Additional Insureds | G2: Directors & Officers | H2: Adoption & Foster Care
A3: 2001-2002 | B3: Adult Day Care | C3: Athletics | D3: General Liability | E3: Owned Autos | F3: Multiple Named Insureds | G3: Educators Legal Liability | H3: Adult Day Care
A4: 2002-2003 | B4: Child Day Care and Special Learning | C4: Camps | D4: Professional Liability | E4: Claims-Made Policy | F4: Taxes & Fees | G4: Employment Practices | H4: Child Day Care and Special Learning
A5: 2003-2004 | B5: Community Action Organizations | C5: Construction | D5: Auto | E5: Required Additional Insureds | F5: Standard Terms & Conditions | G5: Fiduciary | H5: Community Action Organizations
A6: 2004-2005 | B6: Educational Service and Support, including Libraries | C6: Contracting | D6: Medical Malpractice | E6: Multiple Named Insureds | F6: Recommended Submission Data | H6: Educational Service and Support, including Libraries
A7: 2005-2006 | B7: Foundations & Trusts | C7: Improvements/Betterments To Owned Facilities | D7: Crime | E7: Taxes & Fees | F7: Mimimum Fields Required For ACORDs | H7: Foundations & Trusts
A8: 2006-2007 | B8: Healthcare Advocacy | C8: International Travel | D8: Umbrella | E8: Standard Terms & Conditions | H8: Healthcare Advocacy
A9: 2007-2008 | B9: Housing & Shelter | C9: Owned Vehicles | D9: Sexual Abuse & Molestation | E9: Umbrella Sublimits | H9: Housing & Shelter
A10: 2008-2009 | B10: Management & Technical Assistance | C10: Professionals that Prescribe Drugs | D10: Educators Legal Liability | E10: Cyber Sublimits & Deductibles | H10: Management & Technical Assistance
A11: 2010-2011 | B11: Non-Core Education | C11: Recreational | E11: Recommended Submission Data | H11: Non-Core Education
A12: 2011-2012 | B12: Non-Core Other | C12: Renovation | E12: Mimimum Fields Required For ACORDs | H12: Non-Core Other
A13: 2012-2013 | B13: Non-Profit Foundations | C13: Sports | E13: Cyber | H13: Non-Profit Foundations
A14: 2013-2014 | B14: Professional Societies | C14: Teaching Exposure | E14: Minimum Fields Required For ACORDs – Claims-Made Fields | H14: Professional Societies
A15: 2014-2015 | B15: Speciality Hospitals, Clinics & Family Related | H15: Speciality Hospitals, Clinics & Family Related
A16: 2015-2016 | B16: Schools | H16: Schools
A17: 2016-2017 | B17: Centers | H17: Centers
A18: 2017-2018 | B18: Civil Rights & Advocacy Orgs | H18: Civil Rights & Advocacy Orgs
A19: 2018-2019 | B19: Crime & Legal Related | H19: Crime & Legal Related
A20: 2019-2020 | B20: Employment & Training Services | H20: Employment & Training Services
A21: 2020-2021 | B21: Geriatric Services | H21: Geriatric Services
A22: 2021-2022 | B22: Home Health | H22: Home Health
A23: 2022-2023 | B23: Human Service Orgs (Red Cross, Salvation Army, etc.) | H23: Human Service Orgs (Red Cross, Salvation Army, etc.)
A24: 2023-2024 | B24: Mental Health Services | H24: Mental Health Services
B25: Non-Core Health Care | H25: Non-Core Health Care
B26: Nursing & Rehab | H26: Nursing & Rehab
B27: Recreation, Sports & Camps | H27: Recreation, Sports & Camps
B28: Substance Abuse & Addiction Services | H28: Substance Abuse & Addiction Services
B29: Charitable Food Organizations | H29: Charitable Food Organizations
B30: Colleges & Universities | H30: Colleges & Universities
B31: Developmental Disability, Handicap Services & Disabilities | H31: Developmental Disability, Handicap Services & Disabilities
B32: Environment and Animal Related | H32: Environment and Animal Related
B33: Health Care Services & Support | H33: Health Care Services & Support
B34: Hospitals | H34: Hospitals
B35: International, Foreign Affairs & National Security | H35: International, Foreign Affairs & National Security
B36: Museums, Arts & Humanities | H36: Museums, Arts & Humanities
... B40: Youth Services & Development (incl Boys & Girls Clubs, Big Brother/Sister, Scouting) | H40: Youth Services & Development (incl Boys & Girls Clubs, Big Brother/Sister, Scouting)

Sheet WBA-Lists
A1: Line of Business | B1: Policy Type | C1: Priority | D1: Industry | E1: Business Status | F1: Tier
A2: Management Package | B2: Builders Risk | C2: 0% - Policy info received - no shot of winning | D2: Adoption & Foster Care | E2: Lamb | F2: Tier I
A3: Specialty | B3: Commercial Flood | C3: 25% - Opportunity Open - Unclear of Ability to Win | D3: Adult Day Care | E3: CREIS | F3: Tier II
A4: Package | B4: Cyber | C4: 50% - Opportunity Open - Qualified - Working 50/50 Chance of Winning | D4: Charitable Food Organizations | E4: TruePartners | F4: Tier III
A5: Workers Compensation | B5: Earthquake | C5: 75% - Opportunity Open - Qualified - Know whats needed to win - working on execution | D5: Child Day Care | E5: TruePartners - Wheels | F5: Tier IIII
B6: Educators Legal Liability | C6: 100% - Opportunity Open - Qualified - Having Verbal on Winning Quote / or BOR In Hand | D6: Civil Rights & Advocacy Orgs
B7: Excess | D7: Colleges & Universities
B8: Fiduciary | D8: Crime & Legal Related
B9: Owners Interest | D9: Community Action Organizations
B10: Specialty | D10: Developmental Disability, Handicap Services & Disabilities
B11: Student/Volunteer Accident | D11: Educational Service and Support, including Libraries
B12: Travel Accident | D12: Employment & Training Services
D13: Family & Youth Services & Development (incl Boys & Girls Clubs, Big Brother/Sister, Scouting)
D14: Foundations & Trusts
D15: Geriatric Services
D16: Health Care Services & Support
D17: Home Health
D18: Homes & Centers
D19: Housing & Shelter
D20: Human Service Orgs (YMCA, Urban League, Red Cross, Salvation Army, etc.)
D21: Human Services - Other
D22: Mental Health Services
D23: Museums, Arts & Humanities
D24: Nursing & Rehab
... D31: Volunteer Services

Sheet Acord Review
A1: Acord Review
A2: Requested | B2: Attached | C2: Yes | D2: Approved | E2: Complete | F2: 3
A3: Not Needed | B3: Not Needed | C3: No | D3: Denied | E3: Incomplete | F3: 5
A4: Incomplete Information | B4: Completed | E4: Pending | F4: 7
A5: Incomplete Contact

Sheet WBA - Binding
A1: Test Scenario ID | B1: Broker | C1: Broker Fee | D1: Broker Fee Amount | E1: Broker Fee Terms | F1: Premium Payable | G1: Start Date(MM/DD/YYYY) | H1: Bound Date(MM/DD/YYYY) | I1: WBA Close Date(MM/DD/YYYY)
A2: TS_8 | B2: David Warner | C2: 20000 | D2: 20000 | E2: 30000 | F2: 21st Century Cas Co | G2: 04/20/2023 | H2: 04/20/2023 | I2: 04/21/2024

Sheet WBA - EPIC Policy Details
A1: Test Scenario ID
A2: TS_1

Sheet Contacts
A2: Prospect | B2: Yes | C2: PKG
A3: Carrier/Wholesaler | B3: No | C3: WC

Sheet Applicant Information
A1: Test Scenario ID | B1: Applicant Name | C1: ZipCode | D1: State | E1: County | F1: City | G1: Street Address A | H1: Primary Location | I1: FEIN OR SEC | J1: Business Phone Number | K1: Website Address | L1: Effective Date | M1: Policy Term | N1: Expiration Date
A2: Test Scenario_1

Sheet Locations
A1: Test Scenario ID | B1: Location# | C1: ZipCode | D1: State | E1: City | F1: Location Address | G1: SIC | H1: NAICS
A2: Test Scenario_1

Sheet Contact Information
A1: Test Scenario ID | B1: Contact Name | C1: Primary Phone | D1: Primary E-mail Address | E1: Date Of Business Started | F1: Description of Primary Operation | G1: Contact Additional Interest | H1: Additional Interest Name | I1: Additional Interest Address | J1: Rank | K1: Additional Interest Evidence | L1: Reference Loan Number | M1: Interest End Date | N1: LIEN Amount | O1: Phone (A/C, No, Ext.) | P1: Reason for Interest | Q1: E-mail Address | R1: Fax (A/C, No) | S1: Location | T1: Building | U1: Vehicle | V1: Boat | W1: Airport | X1: Aircraft | Y1: Item Class | Z1: Item | AA1: Item Description | AB1: Location Number | AC1: Building Number | AD1: Street | AE1: City | AF1: State | AG1: County | AH1: ZipCode | AI1: Premises Info Interest | AJ1: Full Time Emp | AK1: Part Time Emp | AL1: Description of Operations
A2: Test Scenario_1

Sheet General Information
A1: Test Scenario ID | B1: Question 1 | C1: Parent Company Name 1 | D1: Relationship Description 1 | E1: Owned Percentage 1 | F1: Question 2 | G1: Parent Company Name 2 | H1: Relationship Description 2 | I1: Owned Percentage 2 | J1: Question 3 | K1: Question 3 Reason | L1: Question 3 Describe | M1: Question 4 | N1: Question 4 Description | O1: Question 5 | P1: Question 5 Description | Q1: Question 6 | R1: Question 6 Date Of Occurrence | S1: Question 6 Explanation | T1: Question 6 Resolution | U1: Question 6 Resolve Date | V1: Question 7 | W1: Question 7 Date Of Occurrence | X1: Question 7 Explanation | Y1: Question 7 Resolution | Z1: Question 7 Resolve Date | AA1: Question 8 | AB1: Question 8 Date Of Occurrence | AC1: Question 8 Explanation | AD1: Question 8 Resolution | AE1: Question 8 Resolve Date
A2: Test Scenario_1

Sheet Prior History
A1: Test Scenario ID | B1: Year | C1: Prior History LOB | D1: Other LOB | E1: Carrier | F1: Policy Number | G1: Premium | H1: Effective Date | I1: Expiration Date | J1: Date Of Occurrence | K1: Loss History LOB | L1: Type/Description of Occurrence or Claim | M1: Amount Paid | N1: Amount Reserved | O1: Date of Claim | P1: Subrogation | Q1: Claim Open
A2: Test Scenario_1

Sheet Commercial Liability
A1: Test Scenario ID | B1: Coverages | C1: Coverage Type | D1: Deductible Type | E1: Deductible Amount | F1: Deductible Basis | G1: Each Occurrence | H1: General Aggregate | I1: Products Completed Ops Aggregate | J1: Personal Advertising Injury | K1: Medical Expense | L1: Fire Legal | M1: Damage to Rented Premises | N1: Other Coverages Restrictions and or Endorsements | O1: Location Number | P1: Hazard Number | Q1: Class Code | R1: Premium Basis | S1: Exposure | T1: Classification of Description | U1: Schedule Of Hazards Add | V1: Interest | W1: Name | X1: ZipCode | Y1: State | Z1: County | AA1: City | AB1: Street Address A | AC1: Rank | AD1: Evidence | AE1: Reference Loan Number | AF1: Location | AG1: Building | AH1: Item Class | AI1: Item | AJ1: Item Description | AK1: Employee Benefits Liability | AL1: Number of Employees | AM1: Retroactive Date | AN1: Abuse & Molestation | AO1: AM Limits | AP1: Counselor and Pastoral Liability
A2: Test Scenario_1

Sheet General Liablity Information
A1: Test Scenario ID | B1: Question 1 | C1: Question 1 Details | D1: Question 2 | E1: Question 2 Equipment | F1: Question 2 Type Of Equipment | G1: Question 2 Instruction Given | H1: Question 3 | I1: Question 3 Details | J1: Question 4 | K1: Question 4 Details | L1: Question 5 | M1: Question 5 Details | N1: Question 6 | O1: Number of Apartments | P1: Total Apartment Area (Sq.ft) | Q1: Describe other Lodging Operations | R1: Question 7 | S1: Question 7 Specifications | T1: Question 8 | U1: Question 8 Details | V1: Question 9 | W1: Type of Sport | X1: Extent of Sponsorship | Y1: Age Group | Z1: Contact Sport | AA1: Question 10 | AB1: Question 10 Details | AC1: Question 11 | AD1: Question 11 Details | AE1: Question 12 | AF1: Question 12 Details | AG1: Question 13 | AH1: Question 13 Details | AI1: Question 14 | AJ1: Question 14 Details | AK1: Question 15 | AL1: Question 15 Details
A2: Test Scenario_1

Sheet Property Information
A1: Test Scenario ID | B1: Coverage Location | C1: Building# | D1: Building Description | E1: Subject of Insurance | F1: Amount | G1: Contents | H1: Coins % | I1: Valuation | J1: Causes of Loss | K1: Inflation Guard % | L1: Deductible | M1: Wind Hail Deductible | N1: Theft Deductible | O1: Blanket | P1: Forms & Conditions to Apply | Q1: Business income exposure | R1: Income with extra expense | S1: Agreed Value | T1: Additional Coverage | U1: Construction Type | V1: Distance to Fire Hydrant | W1: Distance to Fire Station | X1: Protection Class | Y1: Number of Stories | Z1: Number of Basements | AA1: Year Built | AB1: Total Area ( Sq. ft.) | AC1: Wiring Year | AD1: Plumbing Year | AE1: Roofing Year | AF1: Heating Year | AG1: Roof Type | AH1: Burglar Alarm Type | AI1: Premises Fire Protection | AJ1: Sprinklers % | AK1: Additional Interest | AL1: Property Interest | AM1: Name | AN1: Address | AO1: Rank | AP1: Property Evidence | AQ1: Reference/Loan Number | AR1: Location | AS1: Building | AT1: Item Class | AU1: Item | AV1: Item Description | AW1: Remarks | AX1: Property Coverage
A2: Test Scenario_1 | AX2: =IF('Applicant Information'!O66 = "", "", 'Applicant Information'!O66)
AX3: =IF('Applicant Information'!O67 = "", "", 'Applicant Information'!O67)
AX4: =IF('Applicant Information'!O68 = "", "", 'Applicant Information'!O68)
AX5: =IF('Applicant Information'!O69 = "", "", 'Applicant Information'!O69)
AX6: =IF('Applicant Information'!O70 = "", "", 'Applicant Information'!O70)
AX7: =IF('Applicant Information'!O71 = "", "", 'Applicant Information'!O71)
AX8: =IF('Applicant Information'!O72 = "", "", 'Applicant Information'!O72)
AX9: =IF('Applicant Information'!O73 = "", "", 'Applicant Information'!O73)
AX10: =IF('Applicant Information'!O74 = "", "", 'Applicant Information'!O74)
AX11: =IF('Applicant Information'!O75 = "", "", 'Applicant Information'!O75)
AX12: =IF('Applicant Information'!O76 = "", "", 'Applicant Information'!O76)
AX13: =IF('Applicant Information'!O77 = "", "", 'Applicant Information'!O77)
AX14: =IF('Applicant Information'!O78 = "", "", 'Applicant Information'!O78)
... AX133: =IF('Applicant Information'!O197 = "", "", 'Applicant Information'!O197)

Sheet Business Auto
A1: Test Scenario ID | B1: Coverage Location | C1: Drivers Information | D1: Drivers Information Name | E1: Drivers Information Marital Status | F1: Drivers Information Date Of Birth | G1: Drivers Information Drivers Lic | H1: Vehicle Description | I1: Vehicle Description Year | J1: Vehicle Description Make | K1: Vehicle Description Model | L1: Vehicle Description VIN | M1: Vehicle Description Vehicle Type | N1: Vehicle Description Symbol/Age | O1: Vehicle Description COMP/OTC SYM | P1: Vehicle Description Collision Symbol | Q1: Vehicle Description License State | R1: Vehicle Description Territory | S1: Vehicle Description Class | T1: Vehicle Description Seat Capacity | U1: Vehicle Description Radius | V1: Vehicle Description Cost New | W1: Vehicle Description Use | X1: Vehicle Description Check Coverages | Y1: Vehicle Description Deductibles | Z1: Vehicle Description Deductible Amount | AA1: Business Auto Coverage
A2: Test Scenario_1 | AA2: =IF('Applicant Information'!P138 = "", "", 'Applicant Information'!P138)
AA3: =IF('Applicant Information'!P139 = "", "", 'Applicant Information'!P139)
AA4: =IF('Applicant Information'!P140 = "", "", 'Applicant Information'!P140)
AA5: =IF('Applicant Information'!P141 = "", "", 'Applicant Information'!P141)
AA6: =IF('Applicant Information'!P142 = "", "", 'Applicant Information'!P142)
AA7: =IF('Applicant Information'!P143 = "", "", 'Applicant Information'!P143)
AA8: =IF('Applicant Information'!P144 = "", "", 'Applicant Information'!P144)
AA9: =IF('Applicant Information'!P145 = "", "", 'Applicant Information'!P145)
AA10: =IF('Applicant Information'!P146 = "", "", 'Applicant Information'!P146)
AA11: =IF('Applicant Information'!P147 = "", "", 'Applicant Information'!P147)
AA12: =IF('Applicant Information'!P148 = "", "", 'Applicant Information'!P148)
AA13: =IF('Applicant Information'!P149 = "", "", 'Applicant Information'!P149)
AA14: =IF('Applicant Information'!P150 = "", "", 'Applicant Information'!P150)
... AA61: =IF('Applicant Information'!P197 = "", "", 'Applicant Information'!P197)

Sheet Crime
A1: Test Scenario ID | B1: Coverage Location | C1: Coverages Employee Theft | D1: Coverages Limit | E1: Coverages Deductible | F1: Forgery Limit | G1: Forgery Deductible | H1: Inside the Premise Theft of Money & Securities | I1: Inside the Premise Limit A | J1: Inside the Premise Deductible A | K1: Inside the Premise Robbery or Burglary of other Property | L1: Inside the Premise Limit B | M1: Inside the Premise Deductible B | N1: Outside the Premises Limit | O1: Outside the Premises Deductible | P1: Money Orders & Counterfeit Paper Currency Limit | Q1: Money Orders & Counterfeit Paper Currency Deductible | R1: Computer Fraud Limit | S1: Computer Fraud Deductible | T1: Remarks | U1: Crime Coverage
A2: Test Scenario_1 | U2: =IF('Applicant Information'!Q48 = "", "", 'Applicant Information'!Q48)
U3: =IF('Applicant Information'!Q49 = "", "", 'Applicant Information'!Q49)
U4: =IF('Applicant Information'!Q50 = "", "", 'Applicant Information'!Q50)
U5: =IF('Applicant Information'!Q51 = "", "", 'Applicant Information'!Q51)
U6: =IF('Applicant Information'!Q52 = "", "", 'Applicant Information'!Q52)
U7: =IF('Applicant Information'!Q53 = "", "", 'Applicant Information'!Q53)
U8: =IF('Applicant Information'!Q54 = "", "", 'Applicant Information'!Q54)
U9: =IF('Applicant Information'!Q55 = "", "", 'Applicant Information'!Q55)
U10: =IF('Applicant Information'!Q56 = "", "", 'Applicant Information'!Q56)
U11: =IF('Applicant Information'!Q57 = "", "", 'Applicant Information'!Q57)
U12: =IF('Applicant Information'!Q58 = "", "", 'Applicant Information'!Q58)
U13: =IF('Applicant Information'!Q59 = "", "", 'Applicant Information'!Q59)
U14: =IF('Applicant Information'!Q60 = "", "", 'Applicant Information'!Q60)
... U151: =IF('Applicant Information'!Q197 = "", "", 'Applicant Information'!Q197)

Sheet Excess Liability
A1: Test Scenario ID | B1: Transaction Type | C1: Excess Liability Coverage | D1: Expiring Policy # | E1: Excess Liability Limit of Liability Each Occurrence Limit | F1: Limit of Liability Aggregate Limit | G1: Primary Location & Subsidiaries Name | H1: Primary Location & Subsidiaries Location | I1: Primary Location & Subsidiaries Description | J1: Primary Location & Subsidiaries Annual Payroll | K1: Primary Location & Subsidiaries Annual Gross Sales | L1: Primary Location & Subsidiaries Foreign Gross Sales | M1: Primary Location & Subsidiaries # Employees | N1: Automobile Liability Carrier / Policy Number | O1: Automobile Liability Policy Effective Date | P1: Automobile Liability Policy Expiration Date | Q1: Automobile Liability Combined Single Limit (Each Accident) | R1: Automobile Liability Rating MOD | S1: General Liability Policy Type | T1: General Liability Carrier / Policy Number | U1: General Liability Policy Effective Date | V1: General Liability Policy Expiration Date | W1: General Liability Each Occurrence Limit | X1: General Liability General Aggregate Limit | Y1: General Liability Products & Completed Ops Aggregate Limit | Z1: General Liability Personal & Advertising Injury Limit | AA1: General Liability Medical Expense Limit | AB1: General Liability Rating MOD | AC1: Uninsured Motorist Limit (UM) | AD1: Underinsured Motorist Limit(UIM) | AE1: Medical Payments Limit | AF1: Umbrella Coverages Coverage | AG1: Excess Liability Vehicle Type | AH1: Units | AI1: Rates | AJ1: # Owned Vehicles | AK1: # Non - Owned Vehicles | AL1: # Leased Vehicles | AM1: Local Radius (in Miles) | AN1: Intermediate Radius (in Miles) | AO1: Long Distance Radius (in Miles) | AP1: Excess Liability Coverage
A2: Test Scenario_1 | AP2: =IF('Applicant Information'!S22 = "", "", 'Applicant Information'!S22)
AP3: =IF('Applicant Information'!S23 = "", "", 'Applicant Information'!S23)
AP4: =IF('Applicant Information'!S24 = "", "", 'Applicant Information'!S24)
AP5: =IF('Applicant Information'!S25 = "", "", 'Applicant Information'!S25)
AP6: =IF('Applicant Information'!S26 = "", "", 'Applicant Information'!S26)
AP7: =IF('Applicant Information'!S27 = "", "", 'Applicant Information'!S27)
AP8: =IF('Applicant Information'!S28 = "", "", 'Applicant Information'!S28)
AP9: =IF('Applicant Information'!S29 = "", "", 'Applicant Information'!S29)
AP10: =IF('Applicant Information'!S30 = "", "", 'Applicant Information'!S30)
AP11: =IF('Applicant Information'!S31 = "", "", 'Applicant Information'!S31)
AP12: =IF('Applicant Information'!S32 = "", "", 'Applicant Information'!S32)
AP13: =IF('Applicant Information'!S33 = "", "", 'Applicant Information'!S33)
AP14: =IF('Applicant Information'!S34 = "", "", 'Applicant Information'!S34)
... AP177: =IF('Applicant Information'!S197 = "", "", 'Applicant Information'!S197)

Sheet Inland Marine
A1: Test Scenario ID | B1: Summary Information Location # | C1: Summary Information Building # | D1: Summary Information Class Code | E1: Summary Information Blanket # | F1: Summary Information Description | G1: Coverages/Cause of Loss Limit | H1: Coverages/Cause of Loss Deductibles | I1: Coverages/Cause of Loss Coinsurance % | J1: Coverages/Cause of Loss Description | K1: Equipment Storage Location # | L1: Equipment Storage Building # | M1: Equipment Storage Maximum Value Inside | N1: Equipment Storage Maximum Value Outside | O1: Inland Marine Coverage
A2: Test Scenario_1 | O2: =IF('Applicant Information'!R85 = "", "", 'Applicant Information'!R85)
O3: =IF('Applicant Information'!R86 = "", "", 'Applicant Information'!R86)
O4: =IF('Applicant Information'!R87 = "", "", 'Applicant Information'!R87)
O5: =IF('Applicant Information'!R88 = "", "", 'Applicant Information'!R88)
O6: =IF('Applicant Information'!R89 = "", "", 'Applicant Information'!R89)
O7: =IF('Applicant Information'!R90 = "", "", 'Applicant Information'!R90)
O8: =IF('Applicant Information'!R91 = "", "", 'Applicant Information'!R91)
O9: =IF('Applicant Information'!R92 = "", "", 'Applicant Information'!R92)
O10: =IF('Applicant Information'!R93 = "", "", 'Applicant Information'!R93)
O11: =IF('Applicant Information'!R94 = "", "", 'Applicant Information'!R94)
O12: =IF('Applicant Information'!R95 = "", "", 'Applicant Information'!R95)
O13: =IF('Applicant Information'!R96 = "", "", 'Applicant Information'!R96)
O14: =IF('Applicant Information'!R97 = "", "", 'Applicant Information'!R97)
... O114: =IF('Applicant Information'!R197 = "", "", 'Applicant Information'!R197)

Sheet Replacement Cost
A1: Test Scenario ID | B1: Coverage Location | C1: Building | D1: Building Description
A2: Test Scenario_1

Sheet Underwriting Question
A1: Test Scenario ID | B1: Question 1 | C1: Question 2 | D1: Question 3 | E1: Question 4 | F1: Question 5 | G1: Question 6 | H1: Question 7 | I1: Question 8 | J1: Question 9 | K1: Question 10 | L1: Question 11
A2: Test Scenario_1

Sheet Documents
A1: Test Scenario ID | B1: Additional Information Form Name | C1: Quote Documents Form Name | D1: Quote Proposal File Path
A2: Test Scenario_1

Sheet Appointment Event
A2: Job Fair
A3: Event Conference
A4: Company Event
A5: Prospect Meeting
A6: Client Meeting
