Workbook
Name Acord_Review: 'Acord Review'!$A$2:$A$5
Name Auto: 'Coverage Checklist'!$D$2:$D$18
Name Budget_Revenue: #REF!
Name Budget_Revenue: #REF!
Name Budget_Revenue: #REF!
Name Budget_Revenue: #REF!
Name Budget_Revenue: #REF!
Name Budget_Revenue: #REF!
Name Budget_Revenue: #REF!
Name Budget_Revenue: #REF!
Name Budget_Revenue: #REF!
Name Builders_Risk: 'Coverage Checklist'!$K$2:$K$28
Name Business_Status: 'WBA-Lists'!$E$2:$E$31
Name City: #REF!
Name City: #REF!
Name City: #REF!
Name City: #REF!
Name City: #REF!
Name City: #REF!
Name City: #REF!
Name City: #REF!
Name City: #REF!
Name Commercial_Flood: 'Coverage Checklist'!$L$2:$L$5
Name Company_Name: #REF!
Name Company_Name: #REF!
Name Company_Name: #REF!
Name Company_Name: #REF!
Name Company_Name: #REF!
Name Company_Name: #REF!
Name Company_Name: #REF!
Name Company_Name: #REF!
Name Company_Name: #REF!
Name Company_Name: #REF!
Name Company_Name: #REF!
Name Contact_Address: #REF!
Name Contact_Address: #REF!
Name Contact_Address: #REF!
Name Contact_Address: #REF!
Name Contact_Address: #REF!
Name Contact_Address: #REF!
Name Contact_Address: #REF!
Name Contact_Address: #REF!
Name Contact_Address: #REF!
Name Contact_Address: #REF!
Name Contact_Address: #REF!
Name Contact_City: #REF!
Name Contact_City: #REF!
Name Contact_City: #REF!
Name Contact_City: #REF!
Name Contact_City: #REF!
Name Contact_City: #REF!
Name Contact_City: #REF!
Name Contact_City: #REF!
Name Contact_City: #REF!
Name Contact_City: #REF!
Name Contact_City: #REF!
Name Contact_ContactType: #REF!
Name Contact_ContactType: #REF!
Name Contact_ContactType: #REF!
Name Contact_ContactType: #REF!

Sheet Test User Level Data
A1: TestCase# | B1: User | C1: Type | D1: State | E1: Revenue Condition | F1: Revenue Limit | G1: Action | H1: Expected Output | I1: Actual Output | J1: Status
A2: TestCase#3 | B2: Bobby Sheppard | C2: Dynamic | D2: NJ | E2: Over | F2: 1000000 | G2: Publish | H2: Only Level1,Level2 Users are able to view the created list.
A3: TestCase#4 | B3: Tom | C3: Static | D3: NJ | E3: Over | F3: 4000000 | G3: Publish | H3: All User Levels are able to view the created list.
A4: TestCase#5 | B4: Conner Sweet | C4: Dynamic | D4: NJ | E4: Between | F4: 1000000,4000000 | G4: Publish | H4: All User Levels are able to view the created list.

Sheet Action Data
A1: TestCase# | B1: Name | C1: Type | D1: State | E1: Revenue Condition | F1: Revenue Limit | G1: Action | H1: Expected Output | I1: Actual Output | J1: Status
A2: TestCase#3 | B2: New Dynamic List-5 | C2: System-Default | D2: NJ | E2: Over | F2: 1000000 | G2: Save | H2: List Name is displayed in the list of Prospects and has Type as "System-Default" and Status as "System-Default"
A3: TestCase#5 | B3: New Dynamic List-6 | C3: Dynamic | D3: NJ | E3: Between | F3: 1000000,4000000 | G3: Save&Close | H3: List Name is displayed in the list of Prospects and has Type as "Dynamic" and Status as "Draft"
A4: TestCase#6 | B4: New Dynamic List-11 | C4: Dynamic | D4: NJ | E4: Upto | F4: 1000000 | G4: Published | H4: List Name is displayed in the list of Prospects and has Type as "Dynamic" and Status as "Published"

Sheet Group List Data- Contacts
A1: TestCase# | B1: Name | C1: Class | D1: Type | E1: Users | F1: Groups and Filters | G1: Condition | H1: Action | I1: Expected Output | J1: Actual Output | K1: Status
A2: TestCase#3 | B2: Static Test List for Contact #1 | C2: Whiteboard Activities | D2: Dynamic | E2: Kevin Corona,Manoj Peruri | F2: Group5,Filter3,Filter5 | G2: And | H2: Publish | I2: List is created with mentioned Name,Class,Type and Filters and then is assigned to mentioned Users

Sheet List Data
A1: TestCase# | B1: Name | C1: Type | D1: State | E1: Revenue Condition | F1: Revenue Limit | G1: Action | H1: Expected Output | I1: Actual Output | J1: Status
A2: TestCase#3 | B2: New Dynamic List-NJ-Over-1000000 | C2: Dynamic | D2: NJ | E2: Over | F2: 1000000 | G2: Publish | H2: All filtered prospect must have State as NJ and Revenue greater than 100000
A3: TestCase#5 | B3: New Dynamic List-NJ-Between-1000000 | C3: Dynamic | D3: NJ | E3: Between | F3: 1000000,4000000 | G3: Publish | H3: All filtered prospect must have State as NJ and Revenue Between 1000000 and 4000000
A4: TestCase#6 | B4: New Dynamic List-NJ-Between-1000000 | C4: Dynamic | D4: NJ | E4: Over | F4: 5000000 | G4: Publish | H4: All filtered prospect must have State as NJ and Revenue Over 5000000

Sheet Prospect Dial Disposition
A2: Did not Leave Voicemail | B2: Adoption & Foster Care
A3: Follow up to a Pitch | B3: Adult Day Care
A4: Left Voicemail | B4: Centers
A5: Non-Core/Remove from Database | B5: Charitable Food Organizations
A6: Pitched to Decision Maker | B6: Child Day Care and Special Learning
A7: Should not be on list | B7: Civil Rights & Advocacy Orgs
A8: No Pitch Made - Talk to Non Decision Maker | B8: Colleges & Universities
A9: No Pitch Made - Talked to Decision Maker | B9: Community Action Organizations
A10: Wrong Phone Number | B10: Crime & Legal Related
B11: Developmental Disability, Handicap Services & Disabilities
B12: Educational Service and Support, including Libraries
B13: Employment & Training Services
B14: Environment and Animal Related
B15: Foundations & Trusts
B16: Geriatric Services
B17: Health Care Services & Support
B18: Healthcare Advocacy
B19: Home Health
B20: Hospitals
B21: Housing & Shelter
B22: Human Service Orgs (Red Cross, Salvation Army, etc.)
... B40: Non-Core Other

Sheet Bind-Bound
A1: Reason
A2: 0-10%
A3: >10%
A4: Unknown
A5: Significantly lower deductibles offered by Lamb
A6: Better limits offered by Lamb
A7: Strong existing Lamb relationship or referral
A8: Lamb service value proposition

Sheet Coverage Checklist
A1: Property | B1: General Liability | C1: Professional Liability | D1: Auto | E1: Medical Malpractice | F1: Crime | G1: Umbrella | H1: Sexual Abuse & Molestation | I1: Educators Legal Liability | J1: Cyber | K1: Builders Risk | L1: Commercial Flood | M1: Earthquake | N1: Excess | O1: Fiduciary | P1: Owners Interest | Q1: Special Events | R1: Student Volunteer Accident | S1: Travel Accident | T1: Services Liability | U1: Workers Compensation | V1: Directors and Officers | W1: Employment Practices
A2: Improvements & Betterments Limit | B2: General Liability Deductible | C2: Deductible | D2: Personal Injury Protection (PIP) - Each Person | E2: Deductible | F2: Forgery or Alteration Deductible | G2: Retention (Umbrella Only) | H2: Deductible | I2: Educators Legal Liability Retention | J2: Breach Response Costs Retention | K2: Deductible | L2: Deductible | M2: Deductible | N2: Retention (Umbrella Only) | O2: Fiduciary Liability Retention | P2: General Liability Deductible | Q2: General Liability Deductible | R2: Deductible | S2: Deductible | T2: Easy & Comprehensive Claim & Incident Reporting | U2: State Safety Credit | V2: Directors & Officers Retention | W2: Employment Practices Liability Retention
A3: Flood Sublimit | B3: Employee Benefits Liability Deductible | C3: Designated Premises Limitation | D3: Optional Basic Economic Loss (OBEL) - Each Person | E3: Designated Premises Limitation | F3: Inside The Premises (Theft) Deductible | G3: General Liability | H3: Designated Premises Limitation | I3: Directors & Officers Retention | J3: Contingent/Dependent Business Interruption & Extra Expense Retention | K3: Flood Deductible | L3: Flood Limit | M3: Earthquake Limit | N3: General Liability | O3: Consolidated Omnibus Budget Reconciliation Act (COBRA) Violations Retention | P3: General Liability Deductible Trigger | Q3: Liquor Liability Deductible | R3: Policy Aggregate | S3: Accidental Death & Dismemberment - Principal Sum | T3: One-Stop Automated Access to All Available Claim Information | U3: Carrier Dividend Plan | V3: Anti-Trust Claims Retention | W3: Non-Monetary Suits Defense Retention
A4: Earthquake Sublimit | B4: Terrorism Risk Insurance Act of 2002 (TRIA) Coverage | C4: Specific Insureds Limitation | D4: Medical Payments - Each Person | E4: Specific Insureds Limitation | F4: Outside The Premises (Theft) Deductible | G4: Employee Benefits Liability | H4: Specific Insureds Limitation | I4: Employment Practices Liability Retention | J4: Reputational / Public Media Event Loss of Income Retention | K4: Earthquake Deductible | L4: Limit | M4: Limit - [User Entry - Allow User To Name] | N4: Professional Liability | O4: Excess Benefits Tax Retention | P4: Terrorism Risk Insurance Act of 2002 (TRIA) Coverage | Q4: Terrorism Risk Insurance Act of 2002 (TRIA) Coverage | R4: AD&D - Loss of Life | S4: AD&D - Loss of One Hand | T4: Claims Advocacy | U4: Do Multiple EINs Apply? | V4: Non-Monetary Suits Defense Retention | W4: Wage and Hour Claims Defense Retention
A5: Equipment Breakdown | B5: Designated Premises Limitation | C5: Defense Inside/Outside the Limit | D5: Statutory Uninsured Motorist | E5: Each Claim / Occurrence | F5: Computer Fraud Deductible | G5: Professional Liability | H5: Definition of "Insured" includes Volunteers | I5: Third Party Employment Practices Liability Retention | J5: Digital Asset Restoration Retention | K5: Policy Limit | L5: Coinsurance | M5: Coinsurance % | N5: Auto Liability | O5: Employee Retirement Income Security Act (ERISA) Violations Retention | P5: Bodily Injury - Mental Anguish & Emotional Distress Exclusion | Q5: Assault & Battery Exclusion | R5: AD&D - Loss of Both Hands | S5: AD&D - Loss of One Foot | T5: Claims-Reserve Reviews With Client’s Carriers | V5: Punitive Damages Exclusion | W5: Class-Action Suits Defense Retention
A6: Property In Transit | B6: Specific Insureds Limitation | C6: Limit | D6: Limit | E6: Aggregate | F6: Funds Transfer Fraud Deductible | G6: Sexual Abuse & Molestation | H6: Defense Inside/Outside the Limit | I6: Non-Monetary Suits Defense Retention | J6: Cyber Extortion / Ransomware Retention | K6: Soft Costs Limit | N6: Educators Legal Liability | O6: Health Insurance Portability and Accountability Act of 1996 (HIPAA) Violations Retention | P6: Specific Insureds Limitation | Q6: Liquor Liability Exclusion | R6: AD&D - Loss of Both Feet | S6: Loss of Sight in One Eye | T6: Claims Review Meetings | V6: Sexual Abuse & Molestation Exclusion | W6: Third Party Liability Retention
A7: Inland Marine Limit | B7: Lead Exclusion | C7: Claims Made | D7: Comprehensive | E7: Defense Inside/Outside the Limit | F7: Money Orders and Counterfeit Currency Deductible | G7: Auto Liability | H7: Limit | I7: Definition of "Insured" includes School Board / Board of Directors | J7: Invoice Manipulation Retention | K7: Earthquake Sublimit | N7: Employee Benefits Liability | O7: IRS Voluntary Settlement Program Violations Retention | P7: Punitive Damages Exclusion | Q7: Each Occurrence | R7: Loss of Sight in Both Eyes | S7: AD&D - Loss of Speech | T7: Experience Modification Review | V7: Each Claim / Occurrence | W7: Wage and Hour Claims Indemnity Retention
A8: Limit | B8: Corporal Punishment Exclusion | D8: Collision | E8: Claims Made | F8: Credit Card Fraud Deductible | G8: Employers Liability | I8: Definition of "Insured" includes Students | J8: Court Attendance Expense Retention | K8: Equipment Breakdown | N8: Sexual Abuse & Molestation | O8: Specific Plans/Insureds Limitation | P8: Each Occurrence | Q8: Products & Completed Operations Aggregate | R8: AD&D - Loss of Hearing | S8: AD&D - Loss of 2+: Hands & Feet | V8: Aggregate | W8: Class-Action Suits Indemnity Retention
A9: Coinsurance % | B9: Punitive Damages Exclusion | D9: Any Auto | F9: Theft of Client Property Deductible | G9: Educators Legal Liability | I9: Definition of "Insured" includes Parent Teacher Associations | J9: Security & Privacy Liability Retention | K9: Existing Structure - Business Personal Property Limit | N9: Employers Liability | O9: Each Claim / Occurrence | P9: Products & Completed Operations Aggregate | Q9: Damage To Rented Premises | R9: AD&D - Loss of 2+: Hands, Feet, Sight in One Eye | S9: AD&D - Loss of 2+: Hands, Feet, Sight in One Eye, Hearing, Speech | V9: Defense Inside/Outside the Limit | W9: Definition of "Third-Party Wrongful Act" includes Sexual Harrassment
A10: Valuation | B10: Bodily Injury - Mental Anguish & Emotional Distress Exclusion | D10: Owned Autos Only | F10: Theft of Client Property | G10: Medical Malpractice | I10: Punitive Damages Exclusion | J10: Bodily Injury - Mental Anguish & Emotional Distress Retention | K10: Hard Costs Limit | N10: Medical Malpractice | O10: Defense Inside/Outside the Limit | P10: Damage To Rented Premises | Q10: Liquor Liability - Each Occurrence | R10: AD&D - Quadriplegia | S10: AD&D - Paraplegia | V10: Defense Separate Limit | W10: Definition of "Third-Party Wrongful Act" includes Invasion of Privacy
A11: Agreed Value / Coinsurance | B11: General Aggregate Applies Per Location | D11: Owned Private Passenger Autos Only | F11: Credit Card Fraud | G11: Limit | I11: Sexual Abuse & Molestation Exclusion | J11: Property Damage Liability Retention | K11: Loss of Rents/Income Limit | N11: Employee Benefits Liability Sublimit | O11: Employee Retirement Income Security Act (ERISA) Violations Sublimit | P11: Limit - [User Entry - Allow User To Name] | Q11: Limit - [User Entry - Allow User To Name] | R11: AD&D - Hemiplegia | S11: AD&D - Uniplegia | V11: Side A (Individual Director) Separate Limit | W11: Punitive Damages Exclusion
A12: Wind/Hail | B12: Employee Benefits Liability Aggregate | D12: Owned Autos Other Than Private Passenger Autos Only | F12: Limit | G12: Policy Form | I12: Defense Inside/Outside the Limit | J12: Regulatory Fines & Penalties Retention | K12: Flood Sublimit | N12: Sexual Abuse & Molestation Sublimit | O12: Health Insurance Portability and Accountability Act of 1996 (HIPAA) Violations Sublimit | P12: General Aggregate | Q12: General Aggregate | R12: AD&D - Loss of Thumb and Index Finger on Same Hand | S12: AD&D - Loss of Life | V12: Non-Monetary Suits Defense Sublimit | W12: Each Claim / Occurrence
A13: Fungus, Wet Rot, Dry Rot | B13: Limit | D13: Owned Autos Subject To No-Fault | F13: Employee Theft / Dishonesty Deductible | G13: Claims Made | I13: Limit | J13: Payment Card Industry (PCI) Fines & Penalties Retention | K13: Existing Structure - Building Limit | N13: Educators Legal Liability Sublimit | O13: IRS Voluntary Settlement Program Violations Sublimit | P13: Personal & Advertising Injury | Q13: Personal & Advertising Injury | R13: Accidental Death & Dismemberment - Principal Sum | S13: AD&D - Loss of Both Hands | V13: Anti-Trust Sublimit | W13: Defense Inside/Outside the Limit
A14: Pollutant Clean-Up and Removal | B14: Claims Made | D14: Owned Autos Subject To A Compulsory Uninsured Motorist Law | I14: D&O Side A (Non-Indemnified Individuals Coverage) | J14: Business Interruption & Extra Expense Retention | K14: Existing Structure - Loss of Income | N14: Limit | O14: Aggregate | P14: Medical Expense | Q14: Medical Expense | R14: AD&D - Loss of One Hand | S14: AD&D - Loss of Both Feet | V14: Limit | W14: Third Party Liability Sublimit
A15: Accounts Receivable | D15: Specifically Described Autos | I15: D&O Side B (Indemnified Individuals Coverage) | J15: System Failure / Loss of Income Retention | K15: Coinsurance % | N15: General Liability Sublimit | O15: Defense Separate Limit | P15: Permission To Occupy | Q15: Liquor Liability Aggregate | R15: AD&D - Loss of One Foot | S15: Loss of Sight in Both Eyes | W15: Wage and Hour Claims (FLSA) Indemnity Sublimit
A16: Electronic Data Processing (EDP) | D16: Mobile Equipment Subject To Compulsory Or Financial Responsibility Or Other Motor Vehicle Insurance Law Only | I16: D&O Side C (Entity Coverage) | J16: Forensic Accounting Retention | K16: Valuation | N16: Professional Liability Sublimit | O16: Consolidated Omnibus Budget Reconciliation Act (COBRA) Violations Sublimit | P16: Address (Physical) | R16: Loss of Sight in One Eye | S16: AD&D - Loss of Hearing | W16: Class-Action Suits Indemnity Sublimit
A17: Mobile Equipment | D17: Claims Made | I17: Employment Practices Liability | J17: Bricking Retention | K17: Address (Physical) | N17: Auto Liability Sublimit | O17: Excess Benefits Tax Sublimit | P17: State (Physical) | R17: AD&D - Loss of Speech | S17: AD&D - Loss of 2+: Hands, Feet, Sight in One Eye | W17: Limit - [User Entry - Allow User To Name]
A18: Personal Property of Others | D18: Retro Date | I18: Third Party Employment Practices Liability | J18: Funds Transfer Fraud Retention | K18: State (Physical) | N18: Medical Malpractice Sublimit | O18: Limit | P18: Occupancy During Construction | R18: AD&D - Loss of 2+: Hands & Feet | S18: AD&D - Quadriplegia | W18: Aggregate
A19: Debris Removal | I19: Non-Monetary Suits Defense Sublimit | J19: Criminal Reward Expense Retention | K19: Square Footage Added | N19: Policy Form | P19: Construction Type | R19: AD&D - Loss of 2+: Hands, Feet, Sight in One Eye, Hearing, Speech | S19: AD&D - Hemiplegia | W19: Defense Separate Limit
A20: Business Income Waiting Period (Hours) | I20: Wage and Hour Claims (FLSA) Indemnity Sublimit | J20: Utility Fraud / Cryptojacking Retention | K20: Project Type | P20: City (Physical) | R20: AD&D - Paraplegia | S20: AD&D - Loss of Thumb and Index Finger on Same Hand | W20: Non-Monetary Suits Defense Sublimit
A21: Inland Marine Deductible | I21: Wage and Hour Claims (FLSA) Defense Sublimit | J21: Media Liability Retention | K21: Existing Structure - Square Footage | P21: Zip Code (Physical) | R21: AD&D - Uniplegia | W21: Wage and Hour Claims (FLSA) Defense Sublimit
A22: Flood Deductible | I22: Class-Action Suits Indemnity Sublimit | J22: Bodily Injury - Physical Injury, Disease, Death Retention | K22: Existing Structure - Year Built | P22: Project Type | W22: Class-Action Suits Defense Sublimit
A23: Earthquake Deductible | I23: Class-Action Suits Defense Sublimit | J23: Pollution Liability Retention | K23: City (Physical) | P23: Rate Per $1,000 Project Cost
A24: Named Storm Deductible | I24: Claims Made | J24: California Consumer Privacy Act (CCPA) Claims Retention | K24: Zip Code (Physical)
A25: Wind/Hail Deductible | J25: Sexual Abuse & Molestation Exclusion | K25: Occupancy During Construction
A26: Ordinance and Law A - Undamaged Portion | J26: Claims Originating from Employee Personal Devices ("BYOD") Exclusion | K26: Construction Type
A27: Ordinance and Law B - Demolition | J27: Management Liability (Directors & Officers) Exclusion | K27: Existing Structure - Construction Type
A28: Ordinance and Law C - Increased Cost of Construction | J28: Multi-Factor Authentication (MFA) Limitation/Warranty | K28: Existing Structure - Stories
J29: Policy Aggregate Limit
J30: Defense Separate Limit
J31: Breach Response Costs Separate Limit
J32: Contingent/Dependent Business Interruption & Extra Expense Sublimit
J33: Reputational / Public Media Event Loss of Income Sublimit
J34: Digital Asset Restoration Sublimit
J35: Cyber Extortion / Ransomware Sublimit
J36: Invoice Manipulation Sublimit
J37: Court Attendance Expense Sublimit
J38: Security & Privacy Liability Sublimit
J39: Bodily Injury - Mental Anguish & Emotional Distress Sublimit
J40: Property Damage Liability Sublimit
...

Sheet Policy-Term Values
A1: Policy Term | B1: Services | C1: Extra Exposures | D1: Coverages | E1: Special Circumstances | F1: Special Circumstances Workers Compensation | G1: Coverages for Management Package | H1: Services-Backup
A2: 2000-2001 | B2: Adoption & Foster Care | C2: Activities | D2: Property | E2: Owned Buildings | F2: Required Additional Insureds | G2: Directors & Officers | H2: Adoption & Foster Care
A3: 2001-2002 | B3: Adult Day Care | C3: Athletics | D3: General Liability | E3: Owned Autos | F3: Multiple Named Insureds | G3: Educators Legal Liability | H3: Adult Day Care
A4: 2002-2003 | B4: Child Day Care and Special Learning | C4: Camps | D4: Professional Liability | E4: Claims-Made Policy | F4: Taxes & Fees | G4: Employment Practices | H4: Child Day Care and Special Learning
A5: 2003-2004 | B5: Community Action Organizations | C5: Construction | D5: Auto | E5: Required Additional Insureds | F5: Standard Terms & Conditions | G5: Fiduciary | H5: Community Action Organizations
A6: 2004-2005 | B6: Educational Service and Support, including Libraries | C6: Contracting | D6: Medical Malpractice | E6: Multiple Named Insureds | F6: Recommended Submission Data | H6: Educational Service and Support, including Libraries
A7: 2005-2006 | B7: Foundations & Trusts | C7: Improvements/Betterments To Owned Facilities | D7: Crime | E7: Taxes & Fees | F7: Mimimum Fields Required For ACORDs | H7: Foundations & Trusts
A8: 2006-2007 | B8: Healthcare Advocacy | C8: International Travel | D8: Umbrella | E8: Standard Terms & Conditions | H8: Healthcare Advocacy
A9: 2007-2008 | B9: Housing & Shelter | C9: Owned Vehicles | D9: Sexual Abuse & Molestation | E9: Umbrella Sublimits | H9: Housing & Shelter
A10: 2008-2009 | B10: Management & Technical Assistance | C10: Professionals that Prescribe Drugs | D10: Educators Legal Liability | E10: Cyber Sublimits & Deductibles | H10: Management & Technical Assistance
A11: 2010-2011 | B11: Non-Core Education | C11: Recreational | E11: Recommended Submission Data | H11: Non-Core Education
A12: 2011-2012 | B12: Non-Core Other | C12: Renovation | E12: Mimimum Fields Required For ACORDs | H12: Non-Core Other
A13: 2012-2013 | B13: Non-Profit Foundations | C13: Sports | E13: Cyber | H13: Non-Profit Foundations
A14: 2013-2014 | B14: Professional Societies | C14: Teaching Exposure | E14: Minimum Fields Required For ACORDs – Claims-Made Fields | H14: Professional Societies
A15: 2014-2015 | B15: Speciality Hospitals, Clinics & Family Related | H15: Speciality Hospitals, Clinics & Family Related
A16: 2015-2016 | B16: Schools | H16: Schools
A17: 2016-2017 | B17: Centers | H17: Centers
A18: 2017-2018 | B18: Civil Rights & Advocacy Orgs | H18: Civil Rights & Advocacy Orgs
A19: 2018-2019 | B19: Crime & Legal Related | H19: Crime & Legal Related
A20: 2019-2020 | B20: Employment & Training Services | H20: Employment & Training Services
A21: 2020-2021 | B21: Geriatric Services | H21: Geriatric Services
A22: 2021-2022 | B22: Home Health | H22: Home Health
A23: 2022-2023 | B23: Human Service Orgs (Red Cross, Salvation Army, etc.) | H23: Human Service Orgs (Red Cross, Salvation Army, etc.)
A24: 2023-2024 | B24: Mental Health Services | H24: Mental Health Services
B25: Non-Core Health Care | H25: Non-Core Health Care
B26: Nursing & Rehab | H26: Nursing & Rehab
B27: Recreation, Sports & Camps | H27: Recreation, Sports & Camps
B28: Substance Abuse & Addiction Services | H28: Substance Abuse & Addiction Services
B29: Charitable Food Organizations | H29: Charitable Food Organizations
B30: Colleges & Universities | H30: Colleges & Universities
B31: Developmental Disability, Handicap Services & Disabilities | H31: Developmental Disability, Handicap Services & Disabilities
B32: Environment and Animal Related | H32: Environment and Animal Related
B33: Health Care Services & Support | H33: Health Care Services & Support
B34: Hospitals | H34: Hospitals
B35: International, Foreign Affairs & National Security | H35: International, Foreign Affairs & National Security
B36: Museums, Arts & Humanities | H36: Museums, Arts & Humanities
... B40: Youth Services & Development (incl Boys & Girls Clubs, Big Brother/Sister, Scouting) | H40: Youth Services & Development (incl Boys & Girls Clubs, Big Brother/Sister, Scouting)

Sheet WBA-Lists
A1: Line of Business | B1: Policy Type | C1: Priority | D1: Industry | E1: Business Status | F1: Tier
A2: Management Package | B2: Builders Risk | C2: 0% - Policy info received - no shot of winning | D2: Adoption & Foster Care | E2: Lamb | F2: Tier I
A3: Specialty | B3: Commercial Flood | C3: 25% - Opportunity Open - Unclear of Ability to Win | D3: Adult Day Care | E3: CREIS | F3: Tier II
A4: Package | B4: Cyber | C4: 50% - Opportunity Open - Qualified - Working 50/50 Chance of Winning | D4: Charitable Food Organizations | E4: TruePartners | F4: Tier III
A5: Workers Compensation | B5: Earthquake | C5: 75% - Opportunity Open - Qualified - Know whats needed to win - working on execution | D5: Child Day Care | E5: TruePartners - Wheels | F5: Tier IIII
B6: Educators Legal Liability | C6: 100% - Opportunity Open - Qualified - Having Verbal on Winning Quote / or BOR In Hand | D6: Civil Rights & Advocacy Orgs
B7: Excess | D7: Colleges & Universities
B8: Fiduciary | D8: Crime & Legal Related
B9: Owners Interest | D9: Community Action Organizations
B10: Specialty | D10: Developmental Disability, Handicap Services & Disabilities
B11: Student/Volunteer Accident | D11: Educational Service and Support, including Libraries
B12: Travel Accident | D12: Employment & Training Services
D13: Family & Youth Services & Development (incl Boys & Girls Clubs, Big Brother/Sister, Scouting)
D14: Foundations & Trusts
D15: Geriatric Services
D16: Health Care Services & Support
D17: Home Health
D18: Homes & Centers
D19: Housing & Shelter
D20: Human Service Orgs (YMCA, Urban League, Red Cross, Salvation Army, etc.)
D21: Human Services - Other
D22: Mental Health Services
D23: Museums, Arts & Humanities
D24: Nursing & Rehab
... D31: Volunteer Services

Sheet Acord Review
A1: Acord Review
A2: Requested | B2: Attached | C2: Yes | D2: Approved | E2: Complete | F2: 3
A3: Not Needed | B3: Not Needed | C3: No | D3: Denied | E3: Incomplete | F3: 5
A4: Incomplete Information | B4: Completed | E4: Pending | F4: 7
A5: Incomplete Contact

Sheet WBA - Binding
A1: Test Scenario ID | B1: Broker | C1: Broker Fee | D1: Broker Fee Amount | E1: Broker Fee Terms | F1: Premium Payable | G1: Start Date(MM/DD/YYYY) | H1: Bound Date(MM/DD/YYYY) | I1: WBA Close Date(MM/DD/YYYY)
A2: TS_8 | B2: David Warner | C2: 20000 | D2: 20000 | E2: 30000 | F2: 21st Century Cas Co | G2: 04/20/2023 | H2: 04/20/2023 | I2: 04/21/2024

Sheet WBA - EPIC Policy Details
A1: Test Scenario ID
A2: TS_1

Sheet Contacts
A2: Prospect | B2: Yes | C2: PKG
A3: Carrier/Wholesaler | B3: No | C3: WC

Sheet Config
A1: Key | B1: Value
A2: Screenshot Location | B2: Screenshot\

Sheet Credentials
A1: Environment Name | B1: Environment | C1: User Name | D1: URL
A2: AgencyIQ | B2: QA | C2: RPA USER | D2: https://aqnext.azurewebsites.net/

Sheet Test Cases
A1: Test Case | B1: Run Test Case | C1: Mandate Run Test Case | D1: Pre-Requisite | E1: Description | F1: Module | G1: Expected Result
A2: TC_Quote Generation | B2: Y | C2: Y | D2: TC_Login Agency IQ | E2: Launches the AQ website. Logs in using predefined credentials from the config file. Clicks on the "Quote" button to initiate a new quote. Selects a predefined Line of Business (LOB) and primary state. Executes flows that navigate through different sections of the website. Enters all required data in each section, fetched dynamically from the config file. | F2: New Quote Generation | G2: New Quote Created.
A3: TC_Quote Upload Acord | B3: N | D3: TC_Login Agency IQ | E3: Launches the AQ website. Logs in using predefined credentials from the config file. Clicks on the "Quote" button to initiate a new quote. Selects a predefined Line of Business (LOB) and primary state. Executes flows that navigate through different sections of the website. Validate all required data in each section, fetched dynamically from the Acord file. | F3: New Quote Upload Acord Generation | G3: New Quote Created.
A4: TC_Edit Quote | B4: N | D4: TC_Login Agency IQ | E4: Launches the AQ website. Logs in using predefined credentials from the config file. Selects the existing Quote Number Executes flows that navigate through different sections of the website. Edit the required data in the different sections, fetched dynamically from the config file. | F4: Edit Quote | G4: Quote Edited Successfully.

Sheet Source Data
A1: Line Of Business | B1: Primary State | C1: Policy Term | D1: Contact Additional Interest | E1: Additional Interest Evidence | F1: Prior History LOB | G1: Coverages | H1: Coverage Type | I1: Deductible Type | J1: Deductible Amt | K1: Deductible Basis | L1: Each Occurrence | M1: General Aggregate | N1: Products Completed Ops Aggregate | O1: Personal Advertising Injury | P1: Medical Expense | Q1: Fire Legal | R1: AM Limits | S1: Question 2 Type Of Equipment | T1: Question 2 Instruction Given | U1: Question 7 Specifications | V1: Age Group | W1: Coins % | X1: Valuation | Y1: Inflation Guard % | Z1: Deductible | AA1: Wind Hail Deductible | AB1: Theft Deductible | AC1: Blanket | AD1: Construction Type | AE1: Premises Fire Protection | AF1: Property Interest | AG1: Property Evidence | AH1: Vehicle Description Vehicle Type | AI1: Vehicle Description Radius | AJ1: Vehicle Description Use | AK1: Vehicle Description Deductibles | AL1: Coverages Employee Theft | AM1: Coverages Deductible | AN1: Forgery Deductible | AO1: Inside the Premise Theft of Money & Securities | AP1: Inside the Premise Deductible A | AQ1: Inside the Premise Robbery or Burglary of other Property | AR1: Inside the Premise Deductible B | AS1: Outside the Premises Deductible | AT1: Money Orders & Counterfeit Paper Currency Deductible | AU1: Computer Fraud Deductible | AV1: Transaction Type | AW1: Excess Liability Coverage Type | AX1: Excess Liability Limit of Liability Each Occurrence Limit | AY1: General Liability Policy Type | AZ1: Excess Liability Vehicle Type | BA1: Deductible Values | BB1: Limits AM | BC1: States | BD1: Vehicle Types BA | BE1: Vehicle Type EL | BF1: Each Occ Limit EL | BG1: Wind Hail Deductible Property | BH1: Ded Amt CL | BI1: Each Occ CL | BJ1: General Agg CL | BK1: Products & Completed Ops Aggregate CL | BL1: Personal & Advertising Injury | BM1: Medical Expense (Any one Person) | BN1: Fire Legal | BO1: Blanket
A2: Package | B2: Georgia | C2: 1 Month | D2: Additional Insured | E2: Certificate | F2: Automobile | G2: Commercial General Liability | H2: Claims Made | I2: BI | J2: $2,000 | K2: Per Occurrence | L2: $100,000 | M2: $2,000,000 | N2: $2,000,000 | O2: $10,000,000 | P2: $1,000 | Q2: $50,000 | R2: 500/1,000 | S2: Large Equipments | T2: Yes | U2: Approved Fence | V2: 12 & Under | W2: 80 | X2: FRC | Y2: 4 | Z2: 250 | AA2: 500 | AB2: 100 | AC2: Building & Contents | AD2: Fire Resistive | AE2: Chemical Systems | AF2: Loss Payee | AG2: Certificate | AH2: Charter Bus | AI2: Local (Upto 50 miles) | AJ2: Farm | AK2: AA | AL2: Blanket | AM2: 5000 | AN2: 5000 | AO2: Schedule | AP2: 25000 | AQ2: Blanket | AR2: 2500 | AS2: 10000 | AT2: 10000 | AU2: 250000 | AV2: New Business | AW2: Excess | AX2: $1,000,000 | AY2: Occurrence | AZ2: Ex Heavy Truck | BA2: 0 | BB2: 50/100 | BC2: Alabama | BD2: Airport Bus/Limo | BE2: Ex Heavy Truck | BF2: $1,000,000 | BG2: 250 | BH2: $250 | BI2: $25,000 | BJ2: $1,000,000 | BK2: $1,000,000 | BL2: $1,000,000 | BM2: $5,000 | BN2: $50,000
A3: Religious Institutions | B3: Connecticut | G3: Commercial General Liability | H3: Occurrence | J3: $2,000 | K3: Per Occurrence | L3: $100,000 | M3: $2,000,000 | N3: $2,000,000 | O3: $10,000,000 | P3: $1,000 | Q3: $50,000 | R3: 500/1,000 | S3: Large Equipments | T3: Yes | U3: Approved Fence | V3: 13 & Under | W3: 80 | X3: FRC | Y3: 4 | AG3: Certificate | AH3: Semi-Trailer | AI3: Local (Upto 50 miles) | AJ3: Farm | AK3: AA | AL3: Blanket | AM3: 5000 | AN3: 5000 | AO3: Blanket | AP3: 25000 | AQ3: Blanket | AR3: 2500 | AS3: 10000 | AT3: 10000 | AU3: 250000 | AV3: New Business | AW3: Excess | AX3: $1,000,000 | AY3: Occurrence | AZ3: Ex Heavy Truck | BA3: 500 | BB3: 500/1,000 | BC3: Colorado | BD3: Charter Bus | BE3: Hired/Non-owned Auto | BG3: 2500 | BH3: $1,000 | BI3: $200,000 | BJ3: $2,000,000 | BK3: $2,000,000 | BL3: $100,000 | BM3: $3,000 | BN3: $250,000
BA5: $1,000 | BB5: 1,000/3,000 | BC5: Connecticut | BD5: Church Bus | BE5: Light Truck | BG5: 5000 | BH5: $2,000 | BI5: $300,000 | BJ5: $2,250,000 | BK5: $2,250,000 | BL5: $200,000 | BM5: $4,000 | BN5: $300,000 | BO5: N/A
BA6: 500 | BB6: 500/1,000 | BC6: Colorado | BD6: Charter Bus | BE6: Hired/Non-owned Auto | BG6: 2500 | BH6: $1,000 | BI6: $200,000 | BJ6: $2,000,000 | BK6: $2,000,000 | BL6: $100,000 | BM6: $3,000 | BN6: $250,000
BA7: $5,000 | BC7: District of Columbia | BD7: Limousine (8 or less seats) | BE7: Other Buses (0-12 Passengers) | BG7: 25000 | BH7: $4,000 | BI7: $500,000 | BJ7: $4,000,000 | BK7: $4,000,000 | BL7: $350,000 | BM7: $10,000 | BN7: $1,000,000
BA8: $10,000 | BC8: Florida | BD8: Limousine (Over 8 seats) | BE8: Other Buses (Over 12 Passengers) | BG8: 50000 | BH8: $5,000 | BI8: $750,000 | BJ8: $5,000,000 | BK8: $5,000,000 | BL8: $500,000 | BN8: Excluded
BA9: $25,000 | BC9: Georgia | BD9: Paratransit | BE9: Owned Auto | BG9: 75000 | BH9: $10,000 | BI9: $1,000,000 | BJ9: $10,000,000 | BK9: $10,000,000 | BL9: $750,000
BA10: $50,000 | BC10: Idaho | BD10: Private Passenger | BE10: Private Passenger | BG10: 100000 | BH10: $15,000 | BI10: $2,000,000 | BJ10: $20,000,000 | BK10: $20,000,000 | BL10: $1,000,000
BA11: $75,000 | BC11: Illinois | BD11: Public Auto NOC | BE11: School Bus | BG11: 0.01 | BH11: $20,000 | BI11: $3,000,000 | BL11: $2,000,000
BA12: $5,00,000 | BC12: Kansas | BD12: Semi-Trailer | BE12: Van/Pickup | BH12: $75,000 | BI12: $10,000,000 | BL12: $5,000,000
BA13: $100,0000 | BC13: Kentucky | BD13: Service or Utility Trailer | BH13: $100,000 | BL13: $10,000,000
BA14: $200,0000 | BC14: Louisiana | BD14: Sightseeing Bus
BC15: Michigan | BD15: Taxicab (All Other)
BC16: Minnesota | BD16: Taxicab (Owner-Driver)
BC17: Mississippi | BD17: Trailer
BC18: Missouri | BD18: Truck
BC19: Montana | BD19: Truck-Tractor
BC20: Nebraska | BD20: Urban Bus
BC21: New Hampshire | BD21: Van Pool (Other)
BC22: New Jersey
BC23: New Mexico
BC24: North Carolina
BC25: North Dakota
BC26: Oklahoma
BC27: Oregon
BC28: Pennsylvania
BC29: Rhode Island
BC30: South Carolina
BC31: South Dakota
BC32: Tennessee
BC33: Texas
... BC40: Wyoming

Sheet Quote Generation
A1: Test Scenario ID | B1: Line Of Business | C1: Primary State
A2: TestScenario_1 | B2: =IF('Source Data'!A2 = "", "", 'Source Data'!A2) -> Package | C2: =IF('Source Data'!B2 = "", "", 'Source Data'!B2) -> Georgia
A3: TestScenario_2 | B3: =IF('Source Data'!A3 = "", "", 'Source Data'!A3) -> Religious Institutions | C3: =IF('Source Data'!B3 = "", "", 'Source Data'!B3) -> Connecticut
B4: =IF('Source Data'!A7 = "", "", 'Source Data'!A7) | C4: =IF('Source Data'!B7 = "", "", 'Source Data'!B7)
B5: =IF('Source Data'!A8 = "", "", 'Source Data'!A8) | C5: =IF('Source Data'!B8 = "", "", 'Source Data'!B8)
B6: =IF('Source Data'!A9 = "", "", 'Source Data'!A9) | C6: =IF('Source Data'!B9 = "", "", 'Source Data'!B9)
B7: =IF('Source Data'!A10 = "", "", 'Source Data'!A10) | C7: =IF('Source Data'!B10 = "", "", 'Source Data'!B10)
B8: =IF('Source Data'!A11 = "", "", 'Source Data'!A11) | C8: =IF('Source Data'!B11 = "", "", 'Source Data'!B11)
B9: =IF('Source Data'!A12 = "", "", 'Source Data'!A12) | C9: =IF('Source Data'!B12 = "", "", 'Source Data'!B12)
B10: =IF('Source Data'!A13 = "", "", 'Source Data'!A13) | C10: =IF('Source Data'!B13 = "", "", 'Source Data'!B13)
B11: =IF('Source Data'!A14 = "", "", 'Source Data'!A14) | C11: =IF('Source Data'!B14 = "", "", 'Source Data'!B14)
B12: =IF('Source Data'!A15 = "", "", 'Source Data'!A15) | C12: =IF('Source Data'!B15 = "", "", 'Source Data'!B15)
B13: =IF('Source Data'!A16 = "", "", 'Source Data'!A16) | C13: =IF('Source Data'!B16 = "", "", 'Source Data'!B16)
B14: =IF('Source Data'!A17 = "", "", 'Source Data'!A17) | C14: =IF('Source Data'!B17 = "", "", 'Source Data'!B17)
B15: =IF('Source Data'!A18 = "", "", 'Source Data'!A18) | C15: =IF('Source Data'!B18 = "", "", 'Source Data'!B18)
... B196: =IF('Source Data'!A199 = "", "", 'Source Data'!A199) | C196: =IF('Source Data'!B199 = "", "", 'Source Data'!B199)

Sheet Mandate Quote Generation
A1: Test Scenario ID | B1: LineOfBusiness | C1: Primary State
B6: =IF('Source Data'!A7 = "", "", 'Source Data'!A7) | C6: =IF('Source Data'!B7 = "", "", 'Source Data'!B7)
B7: =IF('Source Data'!A8 = "", "", 'Source Data'!A8) | C7: =IF('Source Data'!B8 = "", "", 'Source Data'!B8)
B8: =IF('Source Data'!A9 = "", "", 'Source Data'!A9) | C8: =IF('Source Data'!B9 = "", "", 'Source Data'!B9)
B9: =IF('Source Data'!A10 = "", "", 'Source Data'!A10) | C9: =IF('Source Data'!B10 = "", "", 'Source Data'!B10)
B10: =IF('Source Data'!A11 = "", "", 'Source Data'!A11) | C10: =IF('Source Data'!B11 = "", "", 'Source Data'!B11)
B11: =IF('Source Data'!A12 = "", "", 'Source Data'!A12) | C11: =IF('Source Data'!B12 = "", "", 'Source Data'!B12)
B12: =IF('Source Data'!A13 = "", "", 'Source Data'!A13) | C12: =IF('Source Data'!B13 = "", "", 'Source Data'!B13)
B13: =IF('Source Data'!A14 = "", "", 'Source Data'!A14) | C13: =IF('Source Data'!B14 = "", "", 'Source Data'!B14)
B14: =IF('Source Data'!A15 = "", "", 'Source Data'!A15) | C14: =IF('Source Data'!B15 = "", "", 'Source Data'!B15)
B15: =IF('Source Data'!A16 = "", "", 'Source Data'!A16) | C15: =IF('Source Data'!B16 = "", "", 'Source Data'!B16)
B16: =IF('Source Data'!A17 = "", "", 'Source Data'!A17) | C16: =IF('Source Data'!B17 = "", "", 'Source Data'!B17)
B17: =IF('Source Data'!A18 = "", "", 'Source Data'!A18) | C17: =IF('Source Data'!B18 = "", "", 'Source Data'!B18)
... B198: =IF('Source Data'!A199 = "", "", 'Source Data'!A199) | C198: =IF('Source Data'!B199 = "", "", 'Source Data'!B199)

Sheet Applicant Information
A1: Test Scenario ID | B1: Name | C1: ZipCode | D1: County | E1: Street Address A | F1: Primary Location | G1: FEIN OR SEC | H1: Business Phone Number | I1: Website Address | J1: Effective Date | K1: Policy Term | L1: Property Coverage | M1: Business Auto Coverage | N1: Crime Coverage | O1: Inland Marine Coverage | P1: Excess Liability Coverage | Q1: General Liability Coverage
A2: TestScenario_1 | B2: Test_GA_0001 | C2: 30814 | E2: 605 Lamkin Rd | F2: Yes | G2: 410737340 | H2: 8585858585 | J2: 12/4/2024 | K2: =IF('Source Data'!C2 = "", "", 'Source Data'!C2) -> 1 Month | L2: No | M2: No | N2: No | O2: No | P2: No | Q2: Yes
A3: TestScenario_2 | B3: Test_GA_0002 | C3: 30814 | J3: 12/4/2025
K4: =IF('Source Data'!C7 = "", "", 'Source Data'!C7)
K5: =IF('Source Data'!C8 = "", "", 'Source Data'!C8)
K6: =IF('Source Data'!C9 = "", "", 'Source Data'!C9)
K7: =IF('Source Data'!C10 = "", "", 'Source Data'!C10)
K8: =IF('Source Data'!C11 = "", "", 'Source Data'!C11)
K9: =IF('Source Data'!C12 = "", "", 'Source Data'!C12)
K10: =IF('Source Data'!C13 = "", "", 'Source Data'!C13)
K11: =IF('Source Data'!C14 = "", "", 'Source Data'!C14)
K12: =IF('Source Data'!C15 = "", "", 'Source Data'!C15)
K13: =IF('Source Data'!C16 = "", "", 'Source Data'!C16)
K14: =IF('Source Data'!C17 = "", "", 'Source Data'!C17)
K15: =IF('Source Data'!C18 = "", "", 'Source Data'!C18)
... K196: =IF('Source Data'!C199 = "", "", 'Source Data'!C199)

Sheet Locations
A1: Test Scenario ID | B1: ZipCode | C1: Location Address | D1: SIC | E1: NAICS
A2: TestScenario_1 | B2: 77808-2326 | C2: 2490 BOONVILLE RD | D2: 8661 -Religious Organizations | E2: 813110 -Religious Organizations

Sheet Contact Information
A1: Test Scenario ID | B1: Contact Name | C1: Primary Phone | D1: Primary E-mail Address | E1: Date Of Business Started | F1: Description of Primary Operation | G1: Contact Additional Interest | H1: Additional Interest Name | I1: Additional Interest Address | J1: Rank | K1: Additional Interest Evidence | L1: Reference Loan Number | M1: Interest End Date | N1: LIEN Amount | O1: Phone (A/C, No, Ext.) | P1: Reason for Interest | Q1: E-mail Address | R1: Fax (A/C, No) | S1: Location | T1: Building | U1: Vehicle | V1: Boat | W1: Airport | X1: Aircraft | Y1: Item Class | Z1: Item | AA1: Item Description | AB1: Location Number | AC1: Building Number | AD1: Street | AE1: City | AF1: State | AG1: County | AH1: ZipCode | AI1: Premises Info Interest | AJ1: Full Time Emp | AK1: Part Time Emp | AL1: Description of Operations
A2: TestScenario_1 | B2: John | C2: 9898989898 | E2: 45770 | F2: House of Worship Additional Named Insured: Orthodox Mission of Bemidji, Inc. dba All Saints of North America Chapel | G2: =IF('Source Data'!D2 = "", "", 'Source Data'!D2) -> Additional Insured | H2: Thomas | I2: 85 Mountain St., Asheville, NC 28801 | J2: 1 | K2: =IF('Source Data'!E2 = "", "", 'Source Data'!E2) -> Certificate | L2: 123456789 | M2: 45771 | N2: 25000 | O2: 3456789876 | R2: 1234567898 | S2: 1 | T2: 1 | U2: 3 | V2: 4 | W2: 5 | Y2: 6 | Z2: 7 | AA2: provides home care services in New Jersey’s Essex, Bergen, Hudson, Union, Passaic, Morris, Somerset, Middlesex, and Mercer. | AB2: LOC 1 - 605 LAMKIN RD | AC2: 1 | AD2: 605 Lamkin Rd | AF2: GA | AH2: =IF('[1]Applicant Information'!C3 = "", "", '[1]Applicant Information'!C3) | AI2: Owner | AJ2: 6 | AK2: 7 | AL2: Office
G5: =IF('Source Data'!D7 = "", "", 'Source Data'!D7) | K5: =IF('Source Data'!E7 = "", "", 'Source Data'!E7)
G6: =IF('Source Data'!D7 = "", "", 'Source Data'!D7) | K6: =IF('Source Data'!E7 = "", "", 'Source Data'!E7)
G7: =IF('Source Data'!D8 = "", "", 'Source Data'!D8) | K7: =IF('Source Data'!E8 = "", "", 'Source Data'!E8)
G8: =IF('Source Data'!D9 = "", "", 'Source Data'!D9) | K8: =IF('Source Data'!E9 = "", "", 'Source Data'!E9)
G9: =IF('Source Data'!D10 = "", "", 'Source Data'!D10) | K9: =IF('Source Data'!E10 = "", "", 'Source Data'!E10)
G10: =IF('Source Data'!D11 = "", "", 'Source Data'!D11) | K10: =IF('Source Data'!E11 = "", "", 'Source Data'!E11)
G11: =IF('Source Data'!D12 = "", "", 'Source Data'!D12) | K11: =IF('Source Data'!E12 = "", "", 'Source Data'!E12)
G12: =IF('Source Data'!D13 = "", "", 'Source Data'!D13) | K12: =IF('Source Data'!E13 = "", "", 'Source Data'!E13)
G13: =IF('Source Data'!D14 = "", "", 'Source Data'!D14) | K13: =IF('Source Data'!E14 = "", "", 'Source Data'!E14)
G14: =IF('Source Data'!D15 = "", "", 'Source Data'!D15) | K14: =IF('Source Data'!E15 = "", "", 'Source Data'!E15)
G15: =IF('Source Data'!D16 = "", "", 'Source Data'!D16) | K15: =IF('Source Data'!E16 = "", "", 'Source Data'!E16)
G16: =IF('Source Data'!D17 = "", "", 'Source Data'!D17) | K16: =IF('Source Data'!E17 = "", "", 'Source Data'!E17)
G17: =IF('Source Data'!D18 = "", "", 'Source Data'!D18) | K17: =IF('Source Data'!E18 = "", "", 'Source Data'!E18)
... G198: =IF('Source Data'!D199 = "", "", 'Source Data'!D199) | K198: =IF('Source Data'!E199 = "", "", 'Source Data'!E199)
G199: =IF('Source Data'!D200 = "", "", 'Source Data'!D200) | K199: =IF('Source Data'!E195 = "", "", 'Source Data'!E195)
K200: =IF('Source Data'!E196 = "", "", 'Source Data'!E196)
K201: =IF('Source Data'!E197 = "", "", 'Source Data'!E197)
K202: =IF('Source Data'!E198 = "", "", 'Source Data'!E198)
K203: =IF('Source Data'!E199 = "", "", 'Source Data'!E199)
K204: =IF('Source Data'!E200 = "", "", 'Source Data'!E200)
K205: =IF('Source Data'!E201 = "", "", 'Source Data'!E201)
K206: =IF('Source Data'!E202 = "", "", 'Source Data'!E202)
K207: =IF('Source Data'!E203 = "", "", 'Source Data'!E203)
K208: =IF('Source Data'!E204 = "", "", 'Source Data'!E204)
K209: =IF('Source Data'!E205 = "", "", 'Source Data'!E205)
K210: =IF('Source Data'!E206 = "", "", 'Source Data'!E206)
K211: =IF('Source Data'!E207 = "", "", 'Source Data'!E207)
... K248: =IF('Source Data'!E244 = "", "", 'Source Data'!E244)

Sheet General Information
A1: Test Scenario ID | B1: Question 1 | C1: Parent Company Name 1 | D1: Relationship Description 1 | E1: Owned Percentage 1 | F1: Question 2 | G1: Parent Company Name 2 | H1: Relationship Description 2 | I1: Owned Percentage 2 | J1: Question 3 | K1: Question 3 Reason | L1: Question 3 Describe | M1: Question 4 | N1: Question 4 Description | O1: Question 5 | P1: Question 5 Description | Q1: Question 6 | R1: Question 6 Date Of Occurrence | S1: Question 6 Explanation | T1: Question 6 Resolution | U1: Question 6 Resolve Date | V1: Question 7 | W1: Question 7 Date Of Occurrence | X1: Question 7 Explanation | Y1: Question 7 Resolution | Z1: Question 7 Resolve Date | AA1: Question 8 | AB1: Question 8 Date Of Occurrence | AC1: Question 8 Explanation | AD1: Question 8 Resolution | AE1: Question 8 Resolve Date
A2: TestScenario_1 | B2: No | F2: Yes | G2: 4 | H2: 5 | I2: 6 | J2: Yes | K2: Non-Payment | L2: 7 | M2: Yes | N2: 8 | O2: Yes | P2: 9 | Q2: No | V2: No | AA2: Yes | AB2: 4/30/2025 | AC2: 17 | AD2: 18 | AE2: 4/30/2025

Sheet Prior History
A1: Test Scenario ID | B1: Year | C1: Prior History LOB | D1: Other LOB | E1: Carrier | F1: Policy Number | G1: Premium | H1: Effective Date | I1: Expiration Date | J1: Date Of Occurrence | K1: Loss History LOB | L1: Type/Description of Occurrence or Claim | M1: Amount Paid | N1: Amount Reserved | O1: Date of Claim | P1: Subrogation | Q1: Claim Open
A2: TestScenario_1 | B2: 2019-2020 | C2: =IF('Source Data'!F2 = "", "", 'Source Data'!F2) -> Automobile | E2: Western World | F2: 123456AD | G2: 5000 | H2: 45771 | I2: 45772 | J2: 45773 | K2: Prop | L2: Prop Water Damage | M2: 50000 | N2: 0 | O2: 45771 | P2: Yes | Q2: No
C3: =IF('Source Data'!F7 = "", "", 'Source Data'!F7)
C4: =IF('Source Data'!F8 = "", "", 'Source Data'!F8)
C5: =IF('Source Data'!F9 = "", "", 'Source Data'!F9)
C6: =IF('Source Data'!F10 = "", "", 'Source Data'!F10)
C7: =IF('Source Data'!F11 = "", "", 'Source Data'!F11)
C8: =IF('Source Data'!F12 = "", "", 'Source Data'!F12)
C9: =IF('Source Data'!F13 = "", "", 'Source Data'!F13)
C10: =IF('Source Data'!F14 = "", "", 'Source Data'!F14)
C11: =IF('Source Data'!F15 = "", "", 'Source Data'!F15)
C12: =IF('Source Data'!F16 = "", "", 'Source Data'!F16)
C13: =IF('Source Data'!F17 = "", "", 'Source Data'!F17)
C14: =IF('Source Data'!F18 = "", "", 'Source Data'!F18)
... C194: =IF('Source Data'!F198 = "", "", 'Source Data'!F198)
C195: =IF('Source Data'!F194 = "", "", 'Source Data'!F194)
C196: =IF('Source Data'!F195 = "", "", 'Source Data'!F195)
C197: =IF('Source Data'!F196 = "", "", 'Source Data'!F196)
C198: =IF('Source Data'!F197 = "", "", 'Source Data'!F197)
C199: =IF('Source Data'!F198 = "", "", 'Source Data'!F198)
C200: =IF('Source Data'!F199 = "", "", 'Source Data'!F199)
C201: =IF('Source Data'!F200 = "", "", 'Source Data'!F200)
C202: =IF('Source Data'!F201 = "", "", 'Source Data'!F201)
C203: =IF('Source Data'!F202 = "", "", 'Source Data'!F202)
C204: =IF('Source Data'!F203 = "", "", 'Source Data'!F203)
C205: =IF('Source Data'!F204 = "", "", 'Source Data'!F204)
C206: =IF('Source Data'!F205 = "", "", 'Source Data'!F205)
... C244: =IF('Source Data'!F243 = "", "", 'Source Data'!F243)

Sheet Commercial Liability
A1: Test Scenario ID | B1: Coverages | C1: Coverage Type | D1: Deductible Type | E1: Deductible Amt | F1: Deductible Basis | G1: Each Occurrence | H1: General Aggregate | I1: Products Completed Ops Aggregate | J1: Personal Advertising Injury | K1: Medical Expense | L1: Fire Legal | M1: Damage to Rented Premises | N1: Other Coverages Restrictions and or Endorsements | O1: Location Number | P1: Hazard Number | Q1: Class Code | R1: Premium Basis | S1: Exposure | T1: Classification of Description | U1: Schedule Of Hazards Add | V1: Interest | W1: Name | X1: ZipCode | Y1: County | Z1: Street Address A | AA1: Rank | AB1: Evidence | AC1: Reference Loan Number | AD1: Location | AE1: Building | AF1: Item Class | AG1: Item | AH1: Item Description | AI1: Employee Benefits Liability | AJ1: Number of Employees | AK1: Retroactive Date | AL1: Abuse & Molestation | AM1: AM Limits | AN1: Counselor and Pastoral Liability
A2: TestScenario_1 | B2: =IF('Source Data'!G2 = "", "", 'Source Data'!G2) -> Commercial General Liability | C2: =IF('Source Data'!H2 = "", "", 'Source Data'!H2) -> Claims Made | D2: =IF('Source Data'!I2 = "", "", 'Source Data'!I2) -> BI | E2: =IF('Source Data'!J2 = "", "", 'Source Data'!J2) -> $2,000 | F2: =IF('Source Data'!K2 = "", "", 'Source Data'!K2) -> Per Occurrence | G2: =IF('Source Data'!L2 = "", "", 'Source Data'!L2) -> $100,000 | H2: =IF('Source Data'!M2 = "", "", 'Source Data'!M2) -> $2,000,000 | I2: =IF('Source Data'!N2 = "", "", 'Source Data'!N2) -> $2,000,000 | ... L2: =IF('Source Data'!Q2 = "", "", 'Source Data'!Q2) -> $50,000 | M2: 1,000 | N2: See attached Additional Coverages overflow. See attached Forms & Endorsements Schedule. | O2: LOC 1 - 605 Lamkin Rd | P2: 1 | Q2: 41650 | R2: Area | S2: 5000 | T2: Church | U2: Yes | V2: Additional Insured | W2: Katty | X2: 30814 | Z2: 605 Lamkin Rd | AA2: 1 | AB2: Certificate | AC2: 123456789 | AD2: 1 | AE2: 1 | AF2: 2 | AG2: 1 | AH2: Coverage | AI2: Yes | AJ2: 5 | AK2: 12/4/2024 | AL2: Yes | AM2: =IF('Source Data'!R2 = "", "", 'Source Data'!R2) -> 500/1,000 | AN2: Yes
A3: TestScenario_2 | B3: =IF('Source Data'!G3 = "", "", 'Source Data'!G3) -> Commercial General Liability | C3: =IF('Source Data'!H3 = "", "", 'Source Data'!H3) -> Occurrence | D3: =IF('Source Data'!I3 = "", "", 'Source Data'!I3) | E3: =IF('Source Data'!J7 = "", "", 'Source Data'!J7) | F3: =IF('Source Data'!K7 = "", "", 'Source Data'!K7) | G3: =IF('Source Data'!L7 = "", "", 'Source Data'!L7) | H3: =IF('Source Data'!M7 = "", "", 'Source Data'!M7) | I3: =IF('Source Data'!N7 = "", "", 'Source Data'!N7) | J3: =IF('Source Data'!O7 = "", "", 'Source Data'!O7) | K3: =IF('Source Data'!P7 = "", "", 'Source Data'!P7) | L3: =IF('Source Data'!Q7 = "", "", 'Source Data'!Q7) | X3: =IF('Applicant Information'!C4 = "", "", 'Applicant Information'!C4) | AM3: =IF('Source Data'!R7 = "", "", 'Source Data'!R7)
B4: =IF('Source Data'!G8 = "", "", 'Source Data'!G8) | C4: =IF('Source Data'!H8 = "", "", 'Source Data'!H8) | D4: =IF('Source Data'!I8 = "", "", 'Source Data'!I8) | E4: =IF('Source Data'!J8 = "", "", 'Source Data'!J8) | F4: =IF('Source Data'!K8 = "", "", 'Source Data'!K8) | G4: =IF('Source Data'!L8 = "", "", 'Source Data'!L8) | H4: =IF('Source Data'!M8 = "", "", 'Source Data'!M8) | I4: =IF('Source Data'!N8 = "", "", 'Source Data'!N8) | ... L4: =IF('Source Data'!Q8 = "", "", 'Source Data'!Q8) | X4: =IF('Applicant Information'!C5 = "", "", 'Applicant Information'!C5) | AM4: =IF('Source Data'!R8 = "", "", 'Source Data'!R8)
B5: =IF('Source Data'!G9 = "", "", 'Source Data'!G9) | C5: =IF('Source Data'!H9 = "", "", 'Source Data'!H9) | D5: =IF('Source Data'!I9 = "", "", 'Source Data'!I9) | E5: =IF('Source Data'!J9 = "", "", 'Source Data'!J9) | F5: =IF('Source Data'!K9 = "", "", 'Source Data'!K9) | G5: =IF('Source Data'!L9 = "", "", 'Source Data'!L9) | H5: =IF('Source Data'!M9 = "", "", 'Source Data'!M9) | I5: =IF('Source Data'!N9 = "", "", 'Source Data'!N9) | ... L5: =IF('Source Data'!Q9 = "", "", 'Source Data'!Q9) | X5: =IF('Applicant Information'!C6 = "", "", 'Applicant Information'!C6) | AM5: =IF('Source Data'!R9 = "", "", 'Source Data'!R9)
B6: =IF('Source Data'!G10 = "", "", 'Source Data'!G10) | C6: =IF('Source Data'!H10 = "", "", 'Source Data'!H10) | D6: =IF('Source Data'!I10 = "", "", 'Source Data'!I10) | E6: =IF('Source Data'!J10 = "", "", 'Source Data'!J10) | F6: =IF('Source Data'!K10 = "", "", 'Source Data'!K10) | G6: =IF('Source Data'!L10 = "", "", 'Source Data'!L10) | H6: =IF('Source Data'!M10 = "", "", 'Source Data'!M10) | I6: =IF('Source Data'!N10 = "", "", 'Source Data'!N10) | ... L6: =IF('Source Data'!Q10 = "", "", 'Source Data'!Q10) | X6: =IF('Applicant Information'!C7 = "", "", 'Applicant Information'!C7) | AM6: =IF('Source Data'!R10 = "", "", 'Source Data'!R10)
B7: =IF('Source Data'!G11 = "", "", 'Source Data'!G11) | C7: =IF('Source Data'!H11 = "", "", 'Source Data'!H11) | D7: =IF('Source Data'!I11 = "", "", 'Source Data'!I11) | E7: =IF('Source Data'!J11 = "", "", 'Source Data'!J11) | F7: =IF('Source Data'!K11 = "", "", 'Source Data'!K11) | G7: =IF('Source Data'!L11 = "", "", 'Source Data'!L11) | H7: =IF('Source Data'!M11 = "", "", 'Source Data'!M11) | I7: =IF('Source Data'!N11 = "", "", 'Source Data'!N11) | ... L7: =IF('Source Data'!Q11 = "", "", 'Source Data'!Q11) | X7: =IF('Applicant Information'!C8 = "", "", 'Applicant Information'!C8) | AM7: =IF('Source Data'!R11 = "", "", 'Source Data'!R11)
B8: =IF('Source Data'!G12 = "", "", 'Source Data'!G12) | C8: =IF('Source Data'!H12 = "", "", 'Source Data'!H12) | D8: =IF('Source Data'!I12 = "", "", 'Source Data'!I12) | E8: =IF('Source Data'!J12 = "", "", 'Source Data'!J12) | F8: =IF('Source Data'!K12 = "", "", 'Source Data'!K12) | G8: =IF('Source Data'!L12 = "", "", 'Source Data'!L12) | H8: =IF('Source Data'!M12 = "", "", 'Source Data'!M12) | I8: =IF('Source Data'!N12 = "", "", 'Source Data'!N12) | ... L8: =IF('Source Data'!Q12 = "", "", 'Source Data'!Q12) | X8: =IF('Applicant Information'!C9 = "", "", 'Applicant Information'!C9) | AM8: =IF('Source Data'!R12 = "", "", 'Source Data'!R12)
B9: =IF('Source Data'!G13 = "", "", 'Source Data'!G13) | C9: =IF('Source Data'!H13 = "", "", 'Source Data'!H13) | D9: =IF('Source Data'!I13 = "", "", 'Source Data'!I13) | E9: =IF('Source Data'!J13 = "", "", 'Source Data'!J13) | F9: =IF('Source Data'!K13 = "", "", 'Source Data'!K13) | G9: =IF('Source Data'!L13 = "", "", 'Source Data'!L13) | H9: =IF('Source Data'!M13 = "", "", 'Source Data'!M13) | I9: =IF('Source Data'!N13 = "", "", 'Source Data'!N13) | ... L9: =IF('Source Data'!Q13 = "", "", 'Source Data'!Q13) | X9: =IF('Applicant Information'!C10 = "", "", 'Applicant Information'!C10) | AM9: =IF('Source Data'!R13 = "", "", 'Source Data'!R13)
B10: =IF('Source Data'!G16 = "", "", 'Source Data'!G16) | C10: =IF('Source Data'!H16 = "", "", 'Source Data'!H16) | D10: =IF('Source Data'!I16 = "", "", 'Source Data'!I16) | E10: =IF('Source Data'!J16 = "", "", 'Source Data'!J16) | F10: =IF('Source Data'!K16 = "", "", 'Source Data'!K16) | G10: =IF('Source Data'!L16 = "", "", 'Source Data'!L16) | H10: =IF('Source Data'!M16 = "", "", 'Source Data'!M16) | I10: =IF('Source Data'!N16 = "", "", 'Source Data'!N16) | ... L10: =IF('Source Data'!Q16 = "", "", 'Source Data'!Q16) | X10: =IF('Applicant Information'!C13 = "", "", 'Applicant Information'!C13) | AM10: =IF('Source Data'!R16 = "", "", 'Source Data'!R16)
B11: =IF('Source Data'!G17 = "", "", 'Source Data'!G17) | C11: =IF('Source Data'!H17 = "", "", 'Source Data'!H17) | D11: =IF('Source Data'!I17 = "", "", 'Source Data'!I17) | E11: =IF('Source Data'!J17 = "", "", 'Source Data'!J17) | F11: =IF('Source Data'!K17 = "", "", 'Source Data'!K17) | G11: =IF('Source Data'!L17 = "", "", 'Source Data'!L17) | H11: =IF('Source Data'!M17 = "", "", 'Source Data'!M17) | I11: =IF('Source Data'!N17 = "", "", 'Source Data'!N17) | ... L11: =IF('Source Data'!Q17 = "", "", 'Source Data'!Q17) | X11: =IF('Applicant Information'!C14 = "", "", 'Applicant Information'!C14) | AM11: =IF('Source Data'!R17 = "", "", 'Source Data'!R17)
B12: =IF('Source Data'!G18 = "", "", 'Source Data'!G18) | C12: =IF('Source Data'!H18 = "", "", 'Source Data'!H18) | D12: =IF('Source Data'!I18 = "", "", 'Source Data'!I18) | E12: =IF('Source Data'!J18 = "", "", 'Source Data'!J18) | F12: =IF('Source Data'!K18 = "", "", 'Source Data'!K18) | G12: =IF('Source Data'!L18 = "", "", 'Source Data'!L18) | H12: =IF('Source Data'!M18 = "", "", 'Source Data'!M18) | I12: =IF('Source Data'!N18 = "", "", 'Source Data'!N18) | ... L12: =IF('Source Data'!Q18 = "", "", 'Source Data'!Q18) | X12: =IF('Applicant Information'!C15 = "", "", 'Applicant Information'!C15) | AM12: =IF('Source Data'!R18 = "", "", 'Source Data'!R18)
B13: =IF('Source Data'!G19 = "", "", 'Source Data'!G19) | C13: =IF('Source Data'!H19 = "", "", 'Source Data'!H19) | D13: =IF('Source Data'!I19 = "", "", 'Source Data'!I19) | E13: =IF('Source Data'!J19 = "", "", 'Source Data'!J19) | F13: =IF('Source Data'!K19 = "", "", 'Source Data'!K19) | G13: =IF('Source Data'!L19 = "", "", 'Source Data'!L19) | H13: =IF('Source Data'!M19 = "", "", 'Source Data'!M19) | I13: =IF('Source Data'!N19 = "", "", 'Source Data'!N19) | ... L13: =IF('Source Data'!Q19 = "", "", 'Source Data'!Q19) | X13: =IF('Applicant Information'!C16 = "", "", 'Applicant Information'!C16) | AM13: =IF('Source Data'!R19 = "", "", 'Source Data'!R19)
B14: =IF('Source Data'!G20 = "", "", 'Source Data'!G20) | C14: =IF('Source Data'!H20 = "", "", 'Source Data'!H20) | D14: =IF('Source Data'!I20 = "", "", 'Source Data'!I20) | E14: =IF('Source Data'!J20 = "", "", 'Source Data'!J20) | F14: =IF('Source Data'!K20 = "", "", 'Source Data'!K20) | G14: =IF('Source Data'!L20 = "", "", 'Source Data'!L20) | H14: =IF('Source Data'!M20 = "", "", 'Source Data'!M20) | I14: =IF('Source Data'!N20 = "", "", 'Source Data'!N20) | ... L14: =IF('Source Data'!Q20 = "", "", 'Source Data'!Q20) | X14: =IF('Applicant Information'!C17 = "", "", 'Applicant Information'!C17) | AM14: =IF('Source Data'!R20 = "", "", 'Source Data'!R20)
B15: =IF('Source Data'!G21 = "", "", 'Source Data'!G21) | C15: =IF('Source Data'!H21 = "", "", 'Source Data'!H21) | D15: =IF('Source Data'!I21 = "", "", 'Source Data'!I21) | E15: =IF('Source Data'!J21 = "", "", 'Source Data'!J21) | F15: =IF('Source Data'!K21 = "", "", 'Source Data'!K21) | G15: =IF('Source Data'!L21 = "", "", 'Source Data'!L21) | H15: =IF('Source Data'!M21 = "", "", 'Source Data'!M21) | I15: =IF('Source Data'!N21 = "", "", 'Source Data'!N21) | ... L15: =IF('Source Data'!Q21 = "", "", 'Source Data'!Q21) | X15: =IF('Applicant Information'!C18 = "", "", 'Applicant Information'!C18) | AM15: =IF('Source Data'!R21 = "", "", 'Source Data'!R21)
B16: =IF('Source Data'!G22 = "", "", 'Source Data'!G22) | C16: =IF('Source Data'!H22 = "", "", 'Source Data'!H22) | D16: =IF('Source Data'!I22 = "", "", 'Source Data'!I22) | E16: =IF('Source Data'!J22 = "", "", 'Source Data'!J22) | F16: =IF('Source Data'!K22 = "", "", 'Source Data'!K22) | G16: =IF('Source Data'!L22 = "", "", 'Source Data'!L22) | H16: =IF('Source Data'!M22 = "", "", 'Source Data'!M22) | I16: =IF('Source Data'!N22 = "", "", 'Source Data'!N22) | ... L16: =IF('Source Data'!Q22 = "", "", 'Source Data'!Q22) | X16: =IF('Applicant Information'!C19 = "", "", 'Applicant Information'!C19) | AM16: =IF('Source Data'!R22 = "", "", 'Source Data'!R22)
B17: =IF('Source Data'!G23 = "", "", 'Source Data'!G23) | C17: =IF('Source Data'!H23 = "", "", 'Source Data'!H23) | D17: =IF('Source Data'!I23 = "", "", 'Source Data'!I23) | E17: =IF('Source Data'!J23 = "", "", 'Source Data'!J23) | F17: =IF('Source Data'!K23 = "", "", 'Source Data'!K23) | G17: =IF('Source Data'!L23 = "", "", 'Source Data'!L23) | H17: =IF('Source Data'!M23 = "", "", 'Source Data'!M23) | I17: =IF('Source Data'!N23 = "", "", 'Source Data'!N23) | ... L17: =IF('Source Data'!Q23 = "", "", 'Source Data'!Q23) | X17: =IF('Applicant Information'!C20 = "", "", 'Applicant Information'!C20) | AM17: =IF('Source Data'!R23 = "", "", 'Source Data'!R23)
B18: =IF('Source Data'!G24 = "", "", 'Source Data'!G24) | C18: =IF('Source Data'!H24 = "", "", 'Source Data'!H24) | D18: =IF('Source Data'!I24 = "", "", 'Source Data'!I24) | E18: =IF('Source Data'!J24 = "", "", 'Source Data'!J24) | F18: =IF('Source Data'!K24 = "", "", 'Source Data'!K24) | G18: =IF('Source Data'!L24 = "", "", 'Source Data'!L24) | H18: =IF('Source Data'!M24 = "", "", 'Source Data'!M24) | I18: =IF('Source Data'!N24 = "", "", 'Source Data'!N24) | ... L18: =IF('Source Data'!Q24 = "", "", 'Source Data'!Q24) | X18: =IF('Applicant Information'!C21 = "", "", 'Applicant Information'!C21) | AM18: =IF('Source Data'!R24 = "", "", 'Source Data'!R24)
B19: =IF('Source Data'!G25 = "", "", 'Source Data'!G25) | C19: =IF('Source Data'!H25 = "", "", 'Source Data'!H25) | D19: =IF('Source Data'!I25 = "", "", 'Source Data'!I25) | E19: =IF('Source Data'!J25 = "", "", 'Source Data'!J25) | F19: =IF('Source Data'!K25 = "", "", 'Source Data'!K25) | G19: =IF('Source Data'!L25 = "", "", 'Source Data'!L25) | H19: =IF('Source Data'!M25 = "", "", 'Source Data'!M25) | I19: =IF('Source Data'!N25 = "", "", 'Source Data'!N25) | ... L19: =IF('Source Data'!Q25 = "", "", 'Source Data'!Q25) | X19: =IF('Applicant Information'!C22 = "", "", 'Applicant Information'!C22) | AM19: =IF('Source Data'!R25 = "", "", 'Source Data'!R25)
